Workbook

Sheet Statistiche_Globali
A1: Statistiche Globali Formula 1
A3: Anno | B3: Campione Piloti | C3: Team Campione | D3: Punti Campione | H3: Pilota | I3: Nazionalità | J3: N° Mondiali Vinti | L3: Scuderia | M3: Nazionalità | N3: N° Mondiali Vinti
A4: 1950 | B4: ='1950'!A4 -> G. Farina | C4: - | D4: ='1950'!I4 -> 45 | H4: J. Fangio | I4: Arg | J4: 5 (1951; 1954; 1955; 1956; 1957) | L4: Cooper Climax | M4: ENG | N4: 2 (1959, 1960)
A5: 1951 | B5: ='1951'!A4 -> J. Fangio | C5: - | D5: ='1951'!J4 -> 50 | H5: J. Brabham | I5: Eng | J5: 2 (1959; 1960) | L5: Ferrari | M5: ITA | N5: 1 (1962)
A6: 1952 | B6: ='1952'!A4 -> A. Ascari | C6: - | D6: ='1952'!J4 -> 63 | H6: A. Ascari | I6: Ita | J6: 2 (1952; 1953) | L6: Vanwall | M6: ENG | N6: 1 (1958)
A7: 1953 | B7: ='1953'!A4 -> A. Ascari | C7: - | D7: ='1953'!K4 -> 49 | H7: P. Hill | I7: Usa | J7: 1 (1961)
A8: 1954 | B8: ='1954'!A4 -> J. Fangio | C8: - | D8: ='1954'!K4 -> 68 | H8: M. Hawthorn | I8: Eng | J8: 1 (1958)
A9: 1955 | B9: ='1955'!A4 -> J. Fangio | C9: - | D9: ='1955'!I4 -> 46 | H9: G. Farina | I9: Ita | J9: 1 (1950)
A10: 1956 | B10: ='1956'!A4 -> J. Fangio | C10: - | D10: ='1956'!J4 -> 53 | H10: G. Hill | I10: Eng | J10: 1 (1962)
A11: 1957 | B11: ='1957'!A4 -> J. Fangio | C11: - | D11: ='1957'!J4 -> 53
A12: 1958 | B12: ='1958'!A4 -> M. Hawthorn | C12: ='1958'!A31 -> Vanwall | D12: ='1958'!N4 -> 68
A13: 1959 | B13: ='1959'!A4 -> J. Brabham | C13: Cooper - Climax | D13: ='1959'!L4 -> 62
A14: 1960 | B14: ='1960'!A4 -> J. Brabham | C14: Cooper - Climax | D14: ='1960'!M4 -> 57
A15: 1961 | B15: ='1961'!A4 -> P. Hill | C15: Ferrari | D15: ='1961'!K4 -> 54
A16: 1962 | B16: ='1962'!A4 -> G. Hill | C16: BRM | D16: ='1962'!L4 -> 65
A17: 1963 | C17: BRM
A18: 1964
A19: 1965
A20: 1966
A21: 1967
A22: 1968
A23: 1969
A24: 1970
A25: 1971
A26: 1972
A27: 1973
A28: 1974
A29: 1975
... A79: 2025

Sheet 1950
A1: Formula 1 - Stagione 1950
A3: Pilota | B3: Gran Bretagna | C3: Monaco | D3: Indianapolis | E3: Svizzera | F3: Belgio | G3: Francia | H3: Italia | I3: Totale | J3: Overall | L3: Random | M3: Performance | N3: Posizione Finale | Q3: COME FUNZIONA
A4: G. Farina | B4: 5 | C4: 9 | D4: 0 | E4: 9 | F4: 7 | G4: 9 | H4: 6 | I4: =SUM(Drivers_1950[[#This Row],[Gran Bretagna]:[Italia]]) -> 45 | J4: 90 | K4: =J4*$J$24 -> 151830 | L4: =J4+RAND()*6 -> 94.336413 | M4: =J4+L4 -> 184.33641 | N4: =RANK(M4,$M$4:$M$23,0) -> 1 | O4: =IF(RAND()<0.08,"DNF","OK") -> OK | Q4: 1. Modifica l'Overall dei piloti
A5: A. Ascari | B5: 8 | C5: 4 | D5: 0 | E5: 4 | F5: 8 | G5: 6 | H5: 4 | I5: =SUM(Drivers_1950[[#This Row],[Gran Bretagna]:[Italia]]) -> 34 | J5: 89 | K5: =J5*$J$24 -> 150143 | L5: =J5+RAND()*6 -> 90.723397 | M5: =J5+L5 -> 179.7234 | N5: =RANK(M5,$M$4:$M$23,0) -> 3 | O5: =IF(RAND()<0.08,"DNF","OK") -> OK | Q5: 2. Premi F9 in Excel per rigenerare la casualità
A6: J. Fangio | B6: 6 | C6: 6 | D6: 0 | E6: 3 | F6: 0 | G6: 0 | H6: 9 | I6: =SUM(Drivers_1950[[#This Row],[Gran Bretagna]:[Italia]]) -> 24 | J6: 89 | K6: =J6*$J$24 -> 150143 | L6: =J6+RAND()*6 -> 89.026193 | M6: =J6+L6 -> 178.02619 | N6: =RANK(M6,$M$4:$M$23,0) -> 6 | O6: =IF(RAND()<0.08,"DNF","OK") -> OK | Q6: 3. Il valore Random simula incidenti, meteo, fortuna ecc.
A7: F. Bonetto | B7: 3 | C7: 3 | D7: 0 | E7: 0 | F7: 4 | G7: 4 | H7: 3 | I7: =SUM(Drivers_1950[[#This Row],[Gran Bretagna]:[Italia]]) -> 17 | J7: 86 | K7: =J7*$J$24 -> 145082 | L7: =J7+RAND()*6 -> 86.045991 | M7: =J7+L7 -> 172.04599 | N7: =RANK(M7,$M$4:$M$23,0) -> 10 | O7: =IF(RAND()<0.08,"DNF","OK") -> OK | Q7: 4. Performance = Overall + Casualità
A8: J. Parsons | B8: 0 | C8: 1 | D8: 9 | E8: 1 | F8: 2 | G8: 1 | H8: 1 | I8: =SUM(Drivers_1950[[#This Row],[Gran Bretagna]:[Italia]]) -> 15 | J8: 89 | K8: =J8*$J$24 -> 150143 | L8: =J8+RAND()*6 -> 89.654891 | M8: =J8+L8 -> 178.65489 | N8: =RANK(M8,$M$4:$M$23,0) -> 5 | O8: =IF(RAND()<0.08,"DNF","OK") -> OK | Q8: 5. Posizione Finale aggiornata automaticamente
A9: P. Etancelin | B9: 0 | C9: 0 | D9: 0 | E9: 6 | F9: 0 | G9: 2 | H9: 0 | I9: =SUM(Drivers_1950[[#This Row],[Gran Bretagna]:[Italia]]) -> 8 | J9: 86 | K9: =J9*$J$24 -> 145082 | L9: =J9+RAND()*6 -> 87.795838 | M9: =J9+L9 -> 173.79584 | N9: =RANK(M9,$M$4:$M$23,0) -> 8 | O9: =IF(RAND()<0.08,"DNF","OK") -> OK
A10: L. Fagioli | B10: 1 | C10: 2 | D10: 0 | E10: 2 | F10: 1 | G10: 0 | H10: 0 | I10: =SUM(Drivers_1950[[#This Row],[Gran Bretagna]:[Italia]]) -> 6 | J10: 87 | K10: =J10*$J$24 -> 146769 | L10: =J10+RAND()*6 -> 92.465406 | M10: =J10+L10 -> 179.46541 | N10: =RANK(M10,$M$4:$M$23,0) -> 4 | O10: =IF(RAND()<0.08,"DNF","OK") -> OK
A11: R. Manzon | B11: 0 | C11: 0 | D11: 0 | E11: 0 | F11: 3 | G11: 3 | H11: 0 | I11: =SUM(Drivers_1950[[#This Row],[Gran Bretagna]:[Italia]]) -> 6 | J11: 85 | K11: =J11*$J$24 -> 143395 | L11: =J11+RAND()*6 -> 85.064957 | M11: =J11+L11 -> 170.06496 | N11: =RANK(M11,$M$4:$M$23,0) -> 11 | O11: =IF(RAND()<0.08,"DNF","OK") -> OK | Q11: Sistema Punti
A12: P. Bira | B12: 2 | C12: 0 | D12: 0 | E12: 0 | F12: 0 | G12: 0 | H12: 0 | I12: =SUM(Drivers_1950[[#This Row],[Gran Bretagna]:[Italia]]) -> 2 | J12: 84 | K12: =J12*$J$24 -> 141708 | L12: =J12+RAND()*6 -> 89.951515 | M12: =J12+L12 -> 173.95152 | N12: =RANK(M12,$M$4:$M$23,0) -> 7 | O12: =IF(RAND()<0.08,"DNF","OK") -> OK | Q12: 1 | R12: 8
A13: R. Sommer | B13: 0 | C13: 0 | D13: 0 | E13: 0 | F13: 0 | G13: 0 | H13: 2 | I13: =SUM(Drivers_1950[[#This Row],[Gran Bretagna]:[Italia]]) -> 2 | J13: 84 | K13: =J13*$J$24 -> 141708 | L13: =J13+RAND()*6 -> 88.868662 | M13: =J13+L13 -> 172.86866 | N13: =RANK(M13,$M$4:$M$23,0) -> 9 | O13: =IF(RAND()<0.08,"DNF","OK") -> OK | Q13: 2 | R13: 6
A14: L. Rosier | B14: 0 | C14: 0 | D14: 0 | E14: 0 | F14: 0 | G14: 0 | H14: 0 | I14: =SUM(Drivers_1950[[#This Row],[Gran Bretagna]:[Italia]]) -> 0 | J14: 83 | K14: =J14*$J$24 -> 140021 | L14: =J14+RAND()*6 -> 86.535996 | M14: =J14+L14 -> 169.536 | N14: =RANK(M14,$M$4:$M$23,0) -> 12 | O14: =IF(RAND()<0.08,"DNF","OK") -> OK | Q14: 3 | R14: 4
A15: P. Whitehead | B15: 0 | C15: 0 | D15: 0 | E15: 0 | F15: 0 | G15: 0 | H15: 0 | I15: =SUM(Drivers_1950[[#This Row],[Gran Bretagna]:[Italia]]) -> 0 | J15: 83 | K15: =J15*$J$24 -> 140021 | L15: =J15+RAND()*6 -> 85.741884 | M15: =J15+L15 -> 168.74188 | N15: =RANK(M15,$M$4:$M$23,0) -> 14 | O15: =IF(RAND()<0.08,"DNF","OK") -> OK | Q15: 4 | R15: 3
A16: L. Chiron | B16: 0 | C16: 0 | D16: 0 | E16: 0 | F16: 0 | G16: 0 | H16: 0 | I16: =SUM(Drivers_1950[[#This Row],[Gran Bretagna]:[Italia]]) -> 0 | J16: 82 | K16: =J16*$J$24 -> 138334 | L16: =J16+RAND()*6 -> 86.860642 | M16: =J16+L16 -> 168.86064 | N16: =RANK(M16,$M$4:$M$23,0) -> 13 | O16: =IF(RAND()<0.08,"DNF","OK") -> OK | Q16: 5 | R16: 2
A17: R. Parnell | B17: 0 | C17: 0 | D17: 0 | E17: 0 | F17: 0 | G17: 0 | H17: 0 | I17: =SUM(Drivers_1950[[#This Row],[Gran Bretagna]:[Italia]]) -> 0 | J17: 81 | K17: =J17*$J$24 -> 136647 | L17: =J17+RAND()*6 -> 83.930753 | M17: =J17+L17 -> 164.93075 | N17: =RANK(M17,$M$4:$M$23,0) -> 15 | O17: =IF(RAND()<0.08,"DNF","OK") -> OK | Q17: 6 | R17: 1
A18: Y. Giraud-Cabantous | B18: 0 | C18: 0 | D18: 0 | E18: 0 | F18: 0 | G18: 0 | H18: 0 | I18: =SUM(Drivers_1950[[#This Row],[Gran Bretagna]:[Italia]]) -> 0 | J18: 88 | K18: =J18*$J$24 -> 148456 | L18: =J18+RAND()*6 -> 91.755306 | M18: =J18+L18 -> 179.75531 | N18: =RANK(M18,$M$4:$M$23,0) -> 2 | O18: =IF(RAND()<0.08,"DNF","OK") -> OK | Q18: 7 | R18: 0
A19: E. Chaboud | B19: 0 | C19: 0 | D19: 0 | E19: 0 | F19: 0 | G19: 0 | H19: 0 | I19: =SUM(Drivers_1950[[#This Row],[Gran Bretagna]:[Italia]]) -> 0 | J19: 81 | K19: =J19*$J$24 -> 136647 | L19: =J19+RAND()*6 -> 83.565289 | M19: =J19+L19 -> 164.56529 | N19: =RANK(M19,$M$4:$M$23,0) -> 16 | O19: =IF(RAND()<0.08,"DNF","OK") -> OK | Q19: 8 | R19: 0
A20: T. De Graffeniried | B20: 0 | C20: 0 | D20: 0 | E20: 0 | F20: 0 | G20: 0 | H20: 0 | I20: =SUM(Drivers_1950[[#This Row],[Gran Bretagna]:[Italia]]) -> 0 | J20: 80 | K20: =J20*$J$24 -> 134960 | L20: =J20+RAND()*6 -> 82.983947 | M20: =J20+L20 -> 162.98395 | N20: =RANK(M20,$M$4:$M$23,0) -> 18 | O20: =IF(RAND()<0.08,"DNF","OK") -> OK | Q20: 9 | R20: 0
A21: B. Gerard | B21: 0 | C21: 0 | D21: 0 | E21: 0 | F21: 0 | G21: 0 | H21: 0 | I21: =SUM(Drivers_1950[[#This Row],[Gran Bretagna]:[Italia]]) -> 0 | J21: 79 | K21: =J21*$J$24 -> 133273 | L21: =J21+RAND()*6 -> 82.026176 | M21: =J21+L21 -> 161.02618 | N21: =RANK(M21,$M$4:$M$23,0) -> 20 | O21: =IF(RAND()<0.08,"DNF","OK") -> OK | Q21: 10 | R21: 0
A22: L. Villoresi | B22: 0 | C22: 0 | D22: 0 | E22: 0 | F22: 0 | G22: 0 | H22: 0 | I22: =SUM(Drivers_1950[[#This Row],[Gran Bretagna]:[Italia]]) -> 0 | J22: 81 | K22: =J22*$J$24 -> 136647 | L22: =J22+RAND()*6 -> 83.342162 | M22: =J22+L22 -> 164.34216 | N22: =RANK(M22,$M$4:$M$23,0) -> 17 | O22: =IF(RAND()<0.08,"DNF","OK") -> OK
A23: L. Wallard | B23: 0 | C23: 0 | D23: 0 | E23: 0 | F23: 0 | G23: 0 | H23: 0 | I23: =SUM(Drivers_1950[[#This Row],[Gran Bretagna]:[Italia]]) -> 0 | J23: 80 | K23: =J23*$J$24 -> 134960 | L23: =J23+RAND()*6 -> 81.37632 | M23: =J23+L23 -> 161.37632 | N23: =RANK(M23,$M$4:$M$23,0) -> 19 | O23: =IF(RAND()<0.08,"DNF","OK") -> DNF
J24: =SUM(J4:J23) -> 1687

Sheet 1951
A1: Formula 1 - Stagione 1951
A3: Pilota | B3: Svizzera | C3: Indianapolis | D3: Belgio | E3: Francia | F3: Gran Bregagna | G3: Germania | H3: Italia | I3: Spagna | J3: Totale | K3: Overall | L3: Colonna1 | M3: Random | N3: Performance | O3: Posizione Finale | Q3: COME FUNZIONA
A4: J. Fangio | B4: 5 | C4: 0 | D4: 6 | E4: 9 | F4: 7 | G4: 9 | H4: 5 | I4: 9 | J4: =SUM(B4:I4) -> 50 | K4: 97 | L4: ='1951'!$K4*'1951'!$K$24 -> 165288 | M4: ='1951'!$K4+RAND()*6 -> 100.64915 | N4: ='1951'!$K4+'1951'!$M4 -> 197.64915 | O4: =RANK(N4,$N$4:$N$23,0) -> 1 | Q4: 1. Modifica l'Overall dei piloti
A5: A. Ascari | B5: 6 | C5: 0 | D5: 9 | E5: 6 | F5: 4 | G5: 6 | H5: 8 | I5: 6 | J5: =SUM(B5:I5) -> 45 | K5: 96 | L5: ='1951'!$K5*'1951'!$K$24 -> 163584 | M5: ='1951'!$K5+RAND()*6 -> 99.097454 | N5: ='1951'!$K5+'1951'!$M5 -> 195.09745 | O5: =RANK(N5,$N$4:$N$23,0) -> 3 | Q5: 2. Premi F9 in Excel per rigenerare la casualità
A6: G. Farina | B6: 8 | C6: 0 | D6: 4 | E6: 4 | F6: 8 | G6: 4 | H6: 6 | I6: 4 | J6: =SUM(B6:I6) -> 38 | K6: 96 | L6: ='1951'!$K6*'1951'!$K$24 -> 163584 | M6: ='1951'!$K6+RAND()*6 -> 100.37844 | N6: ='1951'!$K6+'1951'!$M6 -> 196.37844 | O6: =RANK(N6,$N$4:$N$23,0) -> 2 | Q6: 3. Il valore Random simula incidenti, meteo, fortuna ecc.
A7: J. Gonzalez | B7: 3 | C7: 0 | D7: 3 | E7: 3 | F7: 3 | G7: 2 | H7: 3 | I7: 3 | J7: =SUM(B7:I7) -> 20 | K7: 89 | L7: ='1951'!$K7*'1951'!$K$24 -> 151656 | M7: ='1951'!$K7+RAND()*6 -> 94.297031 | N7: ='1951'!$K7+'1951'!$M7 -> 183.29703 | O7: =RANK(N7,$N$4:$N$23,0) -> 5 | Q7: 4. Performance = Overall + Casualità
A8: L. Wallard | B8: 1 | C8: 9 | D8: 1 | E8: 0 | F8: 1 | G8: 1 | H8: 1 | I8: 1 | J8: =SUM(B8:I8) -> 15 | K8: 87 | L8: ='1951'!$K8*'1951'!$K$24 -> 148248 | M8: ='1951'!$K8+RAND()*6 -> 91.8579 | N8: ='1951'!$K8+'1951'!$M8 -> 178.8579 | O8: =RANK(N8,$N$4:$N$23,0) -> 6 | Q8: 5. Posizione Finale aggiornata automaticamente
A9: L. Villoresi | B9: 2 | C9: 0 | D9: 2 | E9: 2 | F9: 2 | G9: 3 | H9: 2 | I9: 2 | J9: =SUM(B9:I9) -> 15 | K9: 89 | L9: ='1951'!$K9*'1951'!$K$24 -> 151656 | M9: ='1951'!$K9+RAND()*6 -> 94.438134 | N9: ='1951'!$K9+'1951'!$M9 -> 183.43813 | O9: =RANK(N9,$N$4:$N$23,0) -> 4
A10: M. Nazaruk | B10: 0 | C10: 6 | D10: 0 | E10: 0 | F10: 0 | G10: 0 | H10: 0 | I10: 0 | J10: =SUM(B10:I10) -> 6 | K10: 84 | L10: ='1951'!$K10*'1951'!$K$24 -> 143136 | M10: ='1951'!$K10+RAND()*6 -> 84.42711 | N10: ='1951'!$K10+'1951'!$M10 -> 168.42711 | O10: =RANK(N10,$N$4:$N$23,0) -> 11
A11: A. Linden | B11: 0 | C11: 3 | D11: 0 | E11: 0 | F11: 0 | G11: 0 | H11: 0 | I11: 0 | J11: =SUM(B11:I11) -> 3 | K11: 81 | L11: ='1951'!$K11*'1951'!$K$24 -> 138024 | M11: ='1951'!$K11+RAND()*6 -> 86.128404 | N11: ='1951'!$K11+'1951'!$M11 -> 167.1284 | O11: =RANK(N11,$N$4:$N$23,0) -> 12 | Q11: Sistema Punti
A12: M. Ayulo | B12: 0 | C12: 2 | D12: 0 | E12: 0 | F12: 0 | G12: 0 | H12: 0 | I12: 0 | J12: =SUM(B12:I12) -> 2 | K12: 80 | L12: ='1951'!$K12*'1951'!$K$24 -> 136320 | M12: ='1951'!$K12+RAND()*6 -> 84.79186 | N12: ='1951'!$K12+'1951'!$M12 -> 164.79186 | O12: =RANK(N12,$N$4:$N$23,0) -> 15 | Q12: 1 | R12: 8
A13: J. McGrath | B13: 0 | C13: 2 | D13: 0 | E13: 0 | F13: 0 | G13: 0 | H13: 0 | I13: 0 | J13: =SUM(B13:I13) -> 2 | K13: 80 | L13: ='1951'!$K13*'1951'!$K$24 -> 136320 | M13: ='1951'!$K13+RAND()*6 -> 83.915183 | N13: ='1951'!$K13+'1951'!$M13 -> 163.91518 | O13: =RANK(N13,$N$4:$N$23,0) -> 16 | Q13: 2 | R13: 6
A14: B. Ball | B14: 0 | C14: 2 | D14: 0 | E14: 0 | F14: 0 | G14: 0 | H14: 0 | I14: 0 | J14: =SUM(B14:I14) -> 2 | K14: 80 | L14: ='1951'!$K14*'1951'!$K$24 -> 136320 | M14: ='1951'!$K14+RAND()*6 -> 80.621428 | N14: ='1951'!$K14+'1951'!$M14 -> 160.62143 | O14: =RANK(N14,$N$4:$N$23,0) -> 20 | Q14: 3 | R14: 4
A15: L. Fagioli | B15: 0 | C15: 0 | D15: 0 | E15: 1 | F15: 0 | G15: 0 | H15: 0 | I15: 0 | J15: =SUM(B15:I15) -> 1 | K15: 85 | L15: ='1951'!$K15*'1951'!$K$24 -> 144840 | M15: ='1951'!$K15+RAND()*6 -> 86.701076 | N15: ='1951'!$K15+'1951'!$M15 -> 171.70108 | O15: =RANK(N15,$N$4:$N$23,0) -> 10 | Q15: 4 | R15: 3
A16: P.Taruffi | B16: 0 | C16: 0 | D16: 0 | E16: 0 | F16: 0 | G16: 0 | H16: 0 | I16: 0 | J16: =SUM(B16:I16) -> 0 | K16: 86 | L16: ='1951'!$K16*'1951'!$K$24 -> 146544 | M16: ='1951'!$K16+RAND()*6 -> 90.459029 | N16: ='1951'!$K16+'1951'!$M16 -> 176.45903 | O16: =RANK(N16,$N$4:$N$23,0) -> 7 | Q16: 5 | R16: 2
A17: F. Bonetto | B17: 0 | C17: 0 | D17: 0 | E17: 0 | F17: 0 | G17: 0 | H17: 0 | I17: 0 | J17: =SUM(B17:I17) -> 0 | K17: 85 | L17: ='1951'!$K17*'1951'!$K$24 -> 144840 | M17: ='1951'!$K17+RAND()*6 -> 87.926447 | N17: ='1951'!$K17+'1951'!$M17 -> 172.92645 | O17: =RANK(N17,$N$4:$N$23,0) -> 9 | Q17: 6 | R17: 1
A18: R. Parnell | B18: 0 | C18: 0 | D18: 0 | E18: 0 | F18: 0 | G18: 0 | H18: 0 | I18: 0 | J18: =SUM(B18:I18) -> 0 | K18: 84 | L18: ='1951'!$K18*'1951'!$K$24 -> 143136 | M18: ='1951'!$K18+RAND()*6 -> 89.289906 | N18: ='1951'!$K18+'1951'!$M18 -> 173.28991 | O18: =RANK(N18,$N$4:$N$23,0) -> 8 | Q18: 7 | R18: 0
A19: C. Sanesi | B19: 0 | C19: 0 | D19: 0 | E19: 0 | F19: 0 | G19: 0 | H19: 0 | I19: 0 | J19: =SUM(B19:I19) -> 0 | K19: 83 | L19: ='1951'!$K19*'1951'!$K$24 -> 141432 | M19: ='1951'!$K19+RAND()*6 -> 83.627748 | N19: ='1951'!$K19+'1951'!$M19 -> 166.62775 | O19: =RANK(N19,$N$4:$N$23,0) -> 13 | Q19: 8 | R19: 0
A20: L. Rosier | B20: 0 | C20: 0 | D20: 0 | E20: 0 | F20: 0 | G20: 0 | H20: 0 | I20: 0 | J20: =SUM(B20:I20) -> 0 | K20: 82 | L20: ='1951'!$K20*'1951'!$K$24 -> 139728 | M20: ='1951'!$K20+RAND()*6 -> 83.214109 | N20: ='1951'!$K20+'1951'!$M20 -> 165.21411 | O20: =RANK(N20,$N$4:$N$23,0) -> 14 | Q20: 9 | R20: 0
A21: E. de Graffenried | B21: 0 | C21: 0 | D21: 0 | E21: 0 | F21: 0 | G21: 0 | H21: 0 | I21: 0 | J21: =SUM(B21:I21) -> 0 | K21: 80 | L21: ='1951'!$K21*'1951'!$K$24 -> 136320 | M21: ='1951'!$K21+RAND()*6 -> 82.287905 | N21: ='1951'!$K21+'1951'!$M21 -> 162.28791 | O21: =RANK(N21,$N$4:$N$23,0) -> 17 | Q21: 10 | R21: 0
A22: Y. Giraud-Cabantous | B22: 0 | C22: 0 | D22: 0 | E22: 0 | F22: 0 | G22: 0 | H22: 0 | I22: 0 | J22: =SUM(B22:I22) -> 0 | K22: 80 | L22: ='1951'!$K22*'1951'!$K$24 -> 136320 | M22: ='1951'!$K22+RAND()*6 -> 82.16969 | N22: ='1951'!$K22+'1951'!$M22 -> 162.16969 | O22: =RANK(N22,$N$4:$N$23,0) -> 18
A23: A. Linden | B23: 0 | C23: 0 | D23: 0 | E23: 0 | F23: 0 | G23: 0 | H23: 0 | I23: 0 | J23: =SUM(B23:I23) -> 0 | K23: 80 | L23: ='1951'!$K23*'1951'!$K$24 -> 136320 | M23: ='1951'!$K23+RAND()*6 -> 81.386484 | N23: ='1951'!$K23+'1951'!$M23 -> 161.38648 | O23: =RANK(N23,$N$4:$N$23,0) -> 19
K24: =SUM('1951'!$K$4:$K$23) -> 1704

Sheet 1952
A1: Formula 1 - Stagione 1952
A3: Pilota | B3: Svizzera | C3: Indianapolis | D3: Belgio | E3: Francia | F3: Gran Bretagna | G3: Germania | H3: Olanda | I3: Italia | J3: Totale | K3: Overall | M3: Random | N3: Performance | O3: Posizione Finale
A4: A. Ascari | B4: 9 | C4: - | D4: 9 | E4: 9 | F4: 9 | G4: 9 | H4: 9 | I4: 9 | J4: =SUM(B4:I4) -> 63 | K4: 95 | L4: =K4*$K$24 -> 163115 | M4: =K4+RAND()*6 -> 96.684943 | N4: =K4+M4 -> 191.68494 | O4: =RANK(N4,$N$4:$N$23,0) -> 1 | P4: =IF(RAND()<0.08,"DNF","OK") -> OK
A5: G. Farina | B5: 6 | C5: - | D5: 6 | E5: 4 | F5: 6 | G5: 6 | H5: 3 | I5: 3 | J5: =SUM(B5:I5) -> 34 | K5: 90 | L5: =K5*$K$24 -> 154530 | M5: =K5+RAND()*6 -> 91.654619 | N5: =K5+M5 -> 181.65462 | O5: =RANK(N5,$N$4:$N$23,0) -> 5 | P5: =IF(RAND()<0.08,"DNF","OK") -> OK
A6: T. Ruttman | B6: 0 | C6: - | D6: 2 | E6: 6 | F6: 2 | G6: 4 | H6: 0 | I6: 0 | J6: =SUM(B6:I6) -> 14 | K6: 70 | L6: =K6*$K$24 -> 120190 | M6: =K6+RAND()*6 -> 71.798033 | N6: =K6+M6 -> 141.79803 | O6: =RANK(N6,$N$4:$N$23,0) -> 20 | P6: =IF(RAND()<0.08,"DNF","OK") -> DNF
A7: R. Fischer | B7: 0 | C7: 0 | D7: 4 | E7: 0 | F7: 4 | G7: 0 | H7: 6 | I7: 4 | J7: =SUM(B7:I7) -> 18 | K7: 89 | L7: =K7*$K$24 -> 152813 | M7: =K7+RAND()*6 -> 93.820341 | N7: =K7+M7 -> 182.82034 | O7: =RANK(N7,$N$4:$N$23,0) -> 2 | P7: =IF(RAND()<0.08,"DNF","OK") -> OK
A8: M. Hawthorn | B8: 0 | C8: 9 | D8: 0 | E8: 0 | F8: DNF | G8: 0 | H8: 4 | I8: DNF | J8: =SUM(B8:I8) -> 13 | K8: 89 | L8: =K8*$K$24 -> 152813 | M8: =K8+RAND()*6 -> 92.72923 | N8: =K8+M8 -> 181.72923 | O8: =RANK(N8,$N$4:$N$23,0) -> 4 | P8: =IF(RAND()<0.08,"DNF","OK") -> OK
A9: P. Taruffi | B9: 3 | C9: - | D9: 3 | E9: 2 | F9: 1 | G9: 1 | H9: 1 | I9: 0 | J9: =SUM(B9:I9) -> 11 | K9: 88 | L9: =K9*$K$24 -> 151096 | M9: =K9+RAND()*6 -> 88.760656 | N9: =K9+M9 -> 176.76066 | O9: =RANK(N9,$N$4:$N$23,0) -> 9 | P9: =IF(RAND()<0.08,"DNF","OK") -> OK
A10: J. Rathmann | B10: 2 | C10: - | D10: 1 | E10: 0 | F10: 3 | G10: 2 | H10: 0 | I10: 0 | J10: =SUM(B10:I10) -> 8 | K10: 86 | L10: =K10*$K$24 -> 147662 | M10: =K10+RAND()*6 -> 91.777741 | N10: =K10+M10 -> 177.77774 | O10: =RANK(N10,$N$4:$N$23,0) -> 8 | P10: =IF(RAND()<0.08,"DNF","OK") -> OK
A11: L. Villoresi | B11: 4 | C11: - | D11: 0 | E11: 3 | F11: 0 | G11: DNF | H11: 0 | I11: 1 | J11: =SUM(B11:I11) -> 8 | K11: 88 | L11: =K11*$K$24 -> 151096 | M11: =K11+RAND()*6 -> 93.379762 | N11: =K11+M11 -> 181.37976 | O11: =RANK(N11,$N$4:$N$23,0) -> 6 | P11: =IF(RAND()<0.08,"DNF","OK") -> OK
A12: S. Hanks | B12: 0 | C12: 6 | D12: 0 | E12: 0 | F12: 0 | G12: 0 | H12: 0 | I12: 0 | J12: =SUM(B12:I12) -> 6 | K12: 85 | L12: =K12*$K$24 -> 145945 | M12: =K12+RAND()*6 -> 90.448496 | N12: =K12+M12 -> 175.4485 | O12: =RANK(N12,$N$4:$N$23,0) -> 11 | P12: =IF(RAND()<0.08,"DNF","OK") -> OK
A13: J. Behera | B13: 0 | C13: 4 | D13: 0 | E13: DNF | F13: 0 | G13: 0 | H13: 2 | I13: 6 | J13: =SUM(B13:I13) -> 12 | K13: 88 | L13: =K13*$K$24 -> 151096 | M13: =K13+RAND()*6 -> 93.92022 | N13: =K13+M13 -> 181.92022 | O13: =RANK(N13,$N$4:$N$23,0) -> 3 | P13: =IF(RAND()<0.08,"DNF","OK") -> OK
A14: D. Carter | B14: 0 | C14: 3 | D14: 0 | E14: 0 | F14: 0 | G14: 0 | H14: 0 | I14: 0 | J14: =SUM(B14:I14) -> 3 | K14: 83 | L14: =K14*$K$24 -> 142511 | M14: =K14+RAND()*6 -> 86.420466 | N14: =K14+M14 -> 169.42047 | O14: =RANK(N14,$N$4:$N$23,0) -> 19 | P14: =IF(RAND()<0.08,"DNF","OK") -> OK
A15: R. Manzon | B15: 0 | C15: 0 | D15: 0 | E15: 0 | F15: DNF | G15: 3 | H15: 0 | I15: 0 | J15: =SUM(B15:I15) -> 3 | K15: 87 | L15: =K15*$K$24 -> 149379 | M15: =K15+RAND()*6 -> 88.253879 | N15: =K15+M15 -> 175.25388 | O15: =RANK(N15,$N$4:$N$23,0) -> 12 | P15: =IF(RAND()<0.08,"DNF","OK") -> DNF
A16: A. Cross | B16: 1 | C16: - | D16: 0 | E16: 1 | F16: 0 | G16: 0 | H16: 0 | I16: 0 | J16: =SUM(B16:I16) -> 2 | K16: 84 | L16: =K16*$K$24 -> 144228 | M16: =K16+RAND()*6 -> 88.913713 | N16: =K16+M16 -> 172.91371 | O16: =RANK(N16,$N$4:$N$23,0) -> 14 | P16: =IF(RAND()<0.08,"DNF","OK") -> OK | R16: Sistema Punti
A17: J. Gonzalez | B17: 0 | C17: 2 | D17: 0 | E17: 0 | F17: 0 | G17: 0 | H17: 0 | I17: 2 | J17: =SUM(B17:I17) -> 4 | K17: 88 | L17: =K17*$K$24 -> 151096 | M17: =K17+RAND()*6 -> 92.711574 | N17: =K17+M17 -> 180.71157 | O17: =RANK(N17,$N$4:$N$23,0) -> 7 | P17: =IF(RAND()<0.08,"DNF","OK") -> OK | R17: 1 | S17: 8
A18: K. Wharton | B18: 0 | C18: 0 | D18: 0 | E18: 0 | F18: 0 | G18: 0 | H18: 0 | I18: 0 | J18: =SUM(B18:I18) -> 0 | K18: 85 | L18: =K18*$K$24 -> 145945 | M18: =K18+RAND()*6 -> 90.478241 | N18: =K18+M18 -> 175.47824 | O18: =RANK(N18,$N$4:$N$23,0) -> 10 | P18: =IF(RAND()<0.08,"DNF","OK") -> OK | R18: 2 | S18: 6
A19: D. Poore | B19: 0 | C19: 0 | D19: 0 | E19: 0 | F19: 0 | G19: 0 | H19: 0 | I19: 0 | J19: =SUM(B19:I19) -> 0 | K19: 84 | L19: =K19*$K$24 -> 144228 | M19: =K19+RAND()*6 -> 87.330736 | N19: =K19+M19 -> 171.33074 | O19: =RANK(N19,$N$4:$N$23,0) -> 16 | P19: =IF(RAND()<0.08,"DNF","OK") -> OK | R19: 3 | S19: 4
A20: A. Brown | B20: 0 | C20: 0 | D20: 0 | E20: 0 | F20: 0 | G20: 0 | H20: 0 | I20: 0 | J20: =SUM(B20:I20) -> 0 | K20: 84 | L20: =K20*$K$24 -> 144228 | M20: =K20+RAND()*6 -> 87.554801 | N20: =K20+M20 -> 171.5548 | O20: =RANK(N20,$N$4:$N$23,0) -> 15 | P20: =IF(RAND()<0.08,"DNF","OK") -> OK | R20: 4 | S20: 3
A21: M. Trintignant | B21: 0 | C21: 0 | D21: 0 | E21: 0 | F21: 0 | G21: 0 | H21: 0 | I21: 0 | J21: =SUM(B21:I21) -> 0 | K21: 86 | L21: =K21*$K$24 -> 147662 | M21: =K21+RAND()*6 -> 87.081394 | N21: =K21+M21 -> 173.08139 | O21: =RANK(N21,$N$4:$N$23,0) -> 13 | P21: =IF(RAND()<0.08,"DNF","OK") -> OK | R21: 5 | S21: 2
A22: P. Frere | B22: 0 | C22: 0 | D22: 0 | E22: 0 | F22: 0 | G22: 0 | H22: 0 | I22: 0 | J22: =SUM(B22:I22) -> 0 | K22: 84 | L22: =K22*$K$24 -> 144228 | M22: =K22+RAND()*6 -> 87.284912 | N22: =K22+M22 -> 171.28491 | O22: =RANK(N22,$N$4:$N$23,0) -> 17 | P22: =IF(RAND()<0.08,"DNF","OK") -> OK | R22: 6 | S22: 1
A23: E. Thompson | B23: 0 | C23: 0 | D23: 0 | E23: 0 | F23: 0 | G23: 0 | H23: 0 | I23: DNF | J23: =SUM(B23:I23) -> 0 | K23: 84 | L23: =K23*$K$24 -> 144228 | M23: =K23+RAND()*6 -> 87.079574 | N23: =K23+M23 -> 171.07957 | O23: =RANK(N23,$N$4:$N$23,0) -> 18 | P23: =IF(RAND()<0.08,"DNF","OK") -> OK | R23: 7 | S23: 0
K24: =SUM(K4:K23) -> 1717 | R24: 8 | S24: 0
R25: 9 | S25: 0
R26: 10 | S26: 0

Sheet 1953
A1: Formula 1 - Stagione 1953
A3: Pilota | B3: Argentina | C3: Indianapolis | D3: Paesi Bassi | E3: Belgio | F3: Francia | G3: Gran Bretagna | H3: Germania | I3: Svizzera | J3: Italia | K3: Totale | L3: Overall | M3: Colonna1 | N3: Random | O3: Performance | P3: Posizione Finale | Q3: Colonna2
A4: A. Ascari | B4: 4 | C4: 0 | D4: 6 | E4: 8 | F4: 6 | G4: 9 | H4: DNF | I4: 7 | J4: 9 | K4: =SUM(B4:J4) -> 49 | L4: 97 | M4: =L4*$L$24 -> 178965 | N4: =L4+RAND()*6 -> 98.405028 | O4: =L4+N4 -> 195.40503 | P4: =RANK(O4,$O$4:$O$23,0) -> 2 | Q4: =IF(RAND()<0.08,"DNF","OK") -> OK
A5: J. Fangio | B5: 8 | C5: 0 | D5: 8 | E5: 7 | F5: 4 | G5: 6 | H5: 8 | I5: 2 | J5: 4 | K5: =SUM(B5:J5) -> 47 | L5: 96 | M5: =L5*$L$24 -> 177120 | N5: =L5+RAND()*6 -> 96.969195 | O5: =L5+N5 -> 192.9692 | P5: =RANK(O5,$O$4:$O$23,0) -> 5 | Q5: =IF(RAND()<0.08,"DNF","OK") -> DNF
A6: S. Moss | B6: 7 | C6: 0 | D6: 4 | E6: DNF | F6: 9 | G6: 3 | H6: DNF | I6: 8 | J6: 6 | K6: =SUM(B6:J6) -> 37 | L6: 96 | M6: =L6*$L$24 -> 177120 | N6: =L6+RAND()*6 -> 97.083468 | O6: =L6+N6 -> 193.08347 | P6: =RANK(O6,$O$4:$O$23,0) -> 4 | Q6: =IF(RAND()<0.08,"DNF","OK") -> OK
A7: G. Farina | B7: DNF | C7: 0 | D7: 3 | E7: 4 | F7: 3 | G7: 4 | H7: 7 | I7: 4 | J7: 1 | K7: =SUM(B7:J7) -> 26 | L7: 95 | M7: =L7*$L$24 -> 175275 | N7: =L7+RAND()*6 -> 100.87298 | O7: =L7+N7 -> 195.87298 | P7: =RANK(O7,$O$4:$O$23,0) -> 1 | Q7: =IF(RAND()<0.08,"DNF","OK") -> OK
A8: L. Villoresi | B8: 1 | C8: 0 | D8: 1 | E8: 3 | F8: 0 | G8: 0 | H8: DNF | I8: 3 | J8: 3 | K8: =SUM(B8:J8) -> 11 | L8: 95 | M8: =L8*$L$24 -> 175275 | N8: =L8+RAND()*6 -> 98.562554 | O8: =L8+N8 -> 193.56255 | P8: =RANK(O8,$O$4:$O$23,0) -> 3 | Q8: =IF(RAND()<0.08,"DNF","OK") -> OK
A9: B. Vukovic | B9: 0 | C9: 9 | D9: 0 | E9: 0 | F9: 0 | G9: 0 | H9: 0 | I9: 0 | J9: 0 | K9: =SUM(B9:J9) -> 9 | L9: 70 | M9: =L9*$L$24 -> 129150 | N9: =L9+RAND()*6 -> 70.585078 | O9: =L9+N9 -> 140.58508 | P9: =RANK(O9,$O$4:$O$23,0) -> 20 | Q9: =IF(RAND()<0.08,"DNF","OK") -> OK
A10: A. Cross | B10: 2 | C10: 0 | D10: 1 | E10: DNF | F10: 2 | G10: 1 | H10: DNF | I10: 1 | J10: 0 | K10: =SUM(B10:J10) -> 7 | L10: 94 | M10: =L10*$L$24 -> 173430 | N10: =L10+RAND()*6 -> 95.828979 | O10: =L10+N10 -> 189.82898 | P10: =RANK(O10,$O$4:$O$23,0) -> 10 | Q10: =IF(RAND()<0.08,"DNF","OK") -> OK
A11: M. Hawthorn | B11: 0 | C11: 6 | D11: 0 | E11: 0 | F11: 0 | G11: 0 | H11: 0 | I11: 0 | J11: DNF | K11: =SUM(B11:J11) -> 6 | L11: 91 | M11: =L11*$L$24 -> 167895 | N11: =L11+RAND()*6 -> 95.627383 | O11: =L11+N11 -> 186.62738 | P11: =RANK(O11,$O$4:$O$23,0) -> 17 | Q11: =IF(RAND()<0.08,"DNF","OK") -> OK
A12: M. Trintignant | B12: 0 | C12: 2 | D12: 0 | E12: 0 | F12: 0 | G12: 2 | H12: 2 | I12: 0 | J12: 0 | K12: =SUM(B12:J12) -> 6 | L12: 93 | M12: =L12*$L$24 -> 171585 | N12: =L12+RAND()*6 -> 93.966077 | O12: =L12+N12 -> 186.96608 | P12: =RANK(O12,$O$4:$O$23,0) -> 16 | Q12: =IF(RAND()<0.08,"DNF","OK") -> OK
A13: J. McGrath | B13: 3 | C13: 0 | D13: 0 | E13: 1 | F13: 1 | G13: 0 | H13: 0 | I13: 0 | J13: 0 | K13: =SUM(B13:J13) -> 5 | L13: 94 | M13: =L13*$L$24 -> 173430 | N13: =L13+RAND()*6 -> 97.263581 | O13: =L13+N13 -> 191.26358 | P13: =RANK(O13,$O$4:$O$23,0) -> 7 | Q13: =IF(RAND()<0.08,"DNF","OK") -> OK
A14: J. Gonzalez | B14: 0 | C14: 2 | D14: 0 | E14: 0 | F14: 0 | G14: 0 | H14: 3 | I14: 0 | J14: 0 | K14: =SUM(B14:J14) -> 5 | L14: 93 | M14: =L14*$L$24 -> 171585 | N14: =L14+RAND()*6 -> 94.749704 | O14: =L14+N14 -> 187.7497 | P14: =RANK(O14,$O$4:$O$23,0) -> 15 | Q14: =IF(RAND()<0.08,"DNF","OK") -> OK
A15: D. Carter | B15: 0 | C15: 0 | D15: 0 | E15: 0 | F15: 0 | G15: DNF | H15: 4 | I15: 0 | J15: 0 | K15: =SUM(B15:J15) -> 4 | L15: 93 | M15: =L15*$L$24 -> 171585 | N15: =L15+RAND()*6 -> 95.794895 | O15: =L15+N15 -> 188.79489 | P15: =RANK(O15,$O$4:$O$23,0) -> 13 | Q15: =IF(RAND()<0.08,"DNF","OK") -> OK
A16: S. Hanks | B16: 0 | C16: 0 | D16: 0 | E16: 2 | F16: 0 | G16: 0 | H16: DNF | I16: 0 | J16: 2 | K16: =SUM(B16:J16) -> 4 | L16: 94 | M16: =L16*$L$24 -> 173430 | N16: =L16+RAND()*6 -> 96.755642 | O16: =L16+N16 -> 190.75564 | P16: =RANK(O16,$O$4:$O$23,0) -> 9 | Q16: =IF(RAND()<0.08,"DNF","OK") -> OK
A17: O. Galvez | B17: 0 | C17: 2 | D17: DNF | E17: 0 | F17: 0 | G17: 0 | H17: DNF | I17: DNF | J17: 0 | K17: =SUM(B17:J17) -> 2 | L17: 93 | M17: =L17*$L$24 -> 171585 | N17: =L17+RAND()*6 -> 98.498455 | O17: =L17+N17 -> 191.49846 | P17: =RANK(O17,$O$4:$O$23,0) -> 6 | Q17: =IF(RAND()<0.08,"DNF","OK") -> OK
A18: F. Agabashian | B18: DNF | C18: 0 | D18: 2 | E18: 0 | F18: 0 | G18: 0 | H18: 0 | I18: 0 | J18: 0 | K18: =SUM(B18:J18) -> 2 | L18: 93 | M18: =L18*$L$24 -> 171585 | N18: =L18+RAND()*6 -> 97.889321 | O18: =L18+N18 -> 190.88932 | P18: =RANK(O18,$O$4:$O$23,0) -> 8 | Q18: =IF(RAND()<0.08,"DNF","OK") -> OK
A19: P. Russo | B19: 0 | C19: 1.5 | D19: 0 | E19: 0 | F19: 0 | G19: 0 | H19: 0 | I19: 0 | J19: DNF | K19: =SUM(B19:J19) -> 1.5 | L19: 92 | M19: =L19*$L$24 -> 169740 | N19: =L19+RAND()*6 -> 96.212279 | O19: =L19+N19 -> 188.21228 | P19: =RANK(O19,$O$4:$O$23,0) -> 14 | Q19: =IF(RAND()<0.08,"DNF","OK") -> OK
A20: E. de Graffenried | B20: 0 | C20: 1.5 | D20: 0 | E20: 0 | F20: 0 | G20: 0 | H20: 0 | I20: 0 | J20: 0 | K20: =SUM(B20:J20) -> 1.5 | L20: 91 | M20: =L20*$L$24 -> 167895 | N20: =L20+RAND()*6 -> 91.373408 | O20: =L20+N20 -> 182.37341 | P20: =RANK(O20,$O$4:$O$23,0) -> 19 | Q20: =IF(RAND()<0.08,"DNF","OK") -> OK
A21: F. Bonetto | B21: 0 | C21: 0 | D21: 0 | E21: 0 | F21: 0 | G21: 0 | H21: 1 | I21: 0 | J21: 0 | K21: =SUM(B21:J21) -> 1 | L21: 92 | M21: =L21*$L$24 -> 169740 | N21: =L21+RAND()*6 -> 97.27817 | O21: =L21+N21 -> 189.27817 | P21: =RANK(O21,$O$4:$O$23,0) -> 12 | Q21: =IF(RAND()<0.08,"DNF","OK") -> OK
A22: O. Marimon | B22: 0 | C22: 0 | D22: 0 | E22: 0 | F22: 0 | G22: 0 | H22: 0 | I22: 0 | J22: 0 | K22: =SUM(B22:J22) -> 0 | L22: 92 | M22: =L22*$L$24 -> 169740 | N22: =L22+RAND()*6 -> 97.545921 | O22: =L22+N22 -> 189.54592 | P22: =RANK(O22,$O$4:$O$23,0) -> 11 | Q22: =IF(RAND()<0.08,"DNF","OK") -> OK
A23: H. Lang | B23: 0 | C23: 0 | D23: 0 | E23: 0 | F23: 0 | G23: 0 | H23: 0 | I23: 0 | J23: DNF | K23: =SUM(B23:J23) -> 0 | L23: 91 | M23: =L23*$L$24 -> 167895 | N23: =L23+RAND()*6 -> 91.842839 | O23: =L23+N23 -> 182.84284 | P23: =RANK(O23,$O$4:$O$23,0) -> 18 | Q23: =IF(RAND()<0.08,"DNF","OK") -> OK
L24: =SUM('1953'!$L$4:$L$23) -> 1845
S26: 1 | T26: 8
S27: 2 | T27: 6
S28: 3 | T28: 4
S29: 4 | T29: 3
S30: 5 | T30: 2
S31: 6 | T31: 1
S32: 7 | T32: 0
S33: 8 | T33: 0
S34: 9 | T34: 0
S35: 10 | T35: 0

Sheet 1954
A1: Formula 1 - Stagione 1954
A3: Pilota | B3: Argentina | C3: Indianapolis | D3: Belgio | E3: Francia | F3: Gran Bretagna | G3: Germania | H3: Svizzera | I3: Italia | J3: Spagna | K3: Totale | L3: Overall | M3: Colonna1 | N3: Random | O3: Performance | P3: Posizione Finale | Q3: Colonna2 | S3: COME FUNZIONA
A4: J. Fangio | B4: 9 | C4: 0 | D4: 9 | E4: 9 | F4: 9 | G4: 9 | H4: 9 | I4: 5 | J4: 9 | K4: =SUM(B4:J4) -> 68 | L4: 97 | M4: =L4*$L$24 -> 8730 | N4: =L4+RAND()*6 -> 99.888139 | O4: =L4+N4 -> 196.88814 | P4: =RANK(O4,$O$4:$O$29,0) -> 1 | Q4: =IF(RAND()<0.08,"DNF","OK") -> OK | S4: 1. Modifica l'Overall dei piloti
A5: L. Villoresi | B5: 0 | C5: 0 | D5: 6 | E5: 6 | F5: 6 | G5: 4 | H5: 3 | I5: 3 | J5: 6 | K5: =SUM(B5:J5) -> 34 | L5: 95 | M5: =L5*$L$24 -> 8550 | N5: =L5+RAND()*6 -> 98.26228 | O5: =L5+N5 -> 193.26228 | P5: =RANK(O5,$O$4:$O$29,0) -> 2 | Q5: =IF(RAND()<0.08,"DNF","OK") -> OK | S5: 2. Premi F9 in Excel per rigenerare la casualità
A6: G. Farina | B6: 6 | C6: 0 | D6: 4 | E6: DNF | F6: 2 | G6: 6 | H6: 4 | I6: 8 | J6: 4 | K6: =SUM(B6:J6) -> 34 | L6: 95 | M6: =L6*$L$24 -> 8550 | N6: =L6+RAND()*6 -> 97.1476 | O6: =L6+N6 -> 192.1476 | P6: =RANK(O6,$O$4:$O$29,0) -> 5 | Q6: =IF(RAND()<0.08,"DNF","OK") -> OK | S6: 3. Il valore Random simula incidenti, meteo, fortuna ecc.
A7: S. Moss | B7: 4 | C7: 0 | D7: 2 | E7: 4 | F7: 3 | G7: DNF | H7: 6 | I7: 6 | J7: 3 | K7: =SUM(B7:J7) -> 28 | L7: 95 | M7: =L7*$L$24 -> 8550 | N7: =L7+RAND()*6 -> 97.669072 | O7: =L7+N7 -> 192.66907 | P7: =RANK(O7,$O$4:$O$29,0) -> 3 | Q7: =IF(RAND()<0.08,"DNF","OK") -> OK | S7: 4. Performance = Overall + Casualità
A8: R. Mieres | B8: 3 | C8: 0 | D8: 3 | E8: 3 | F8: 4 | G8: 3 | H8: 0 | I8: 2 | J8: 0 | K8: =SUM(B8:J8) -> 18 | L8: 94 | M8: =L8*$L$24 -> 8460 | N8: =L8+RAND()*6 -> 98.146201 | O8: =L8+N8 -> 192.1462 | P8: =RANK(O8,$O$4:$O$29,0) -> 6 | Q8: =IF(RAND()<0.08,"DNF","OK") -> OK | S8: 5. Posizione Finale aggiornata automaticamente
A9: M. Hawthorn | B9: 0 | C9: 0 | D9: 6 | E9: 0 | F9: 1 | G9: 1 | H9: 0 | I9: 1 | J9: 1 | K9: =SUM(B9:J9) -> 10 | L9: 94 | M9: =L9*$L$24 -> 8460 | N9: =L9+RAND()*6 -> 98.543261 | O9: =L9+N9 -> 192.54326 | P9: =RANK(O9,$O$4:$O$29,0) -> 4 | Q9: =IF(RAND()<0.08,"DNF","OK") -> OK
A10: B. Vukovic | B10: 0 | C10: 8 | D10: 0 | E10: 0 | F10: 0 | G10: 0 | H10: 0 | I10: 0 | J10: 0 | K10: =SUM(B10:J10) -> 8 | L10: 70 | M10: =L10*$L$24 -> 6300 | N10: =L10+RAND()*6 -> 73.730817 | O10: =L10+N10 -> 143.73082 | P10: =RANK(O10,$O$4:$O$29,0) -> 22 | Q10: =IF(RAND()<0.08,"DNF","OK") -> OK
A11: J. Gonzalez | B11: 2 | C11: 0 | D11: 1 | E11: 1 | F11: 0 | G11: 2 | H11: 1 | I11: 0 | J11: 0 | K11: =SUM(B11:J11) -> 7 | L11: 93 | M11: =L11*$L$24 -> 8370 | N11: =L11+RAND()*6 -> 94.767623 | O11: =L11+N11 -> 187.76762 | P11: =RANK(O11,$O$4:$O$29,0) -> 8 | Q11: =IF(RAND()<0.08,"DNF","OK") -> OK | S11: Sistema Punti
A12: J. Bryan | B12: 0 | C12: 6 | D12: 0 | E12: 0 | F12: 0 | G12: 0 | H12: 0 | I12: 0 | J12: 0 | K12: =SUM(B12:J12) -> 6 | L12: 70 | M12: =L12*$L$24 -> 6300 | N12: =L12+RAND()*6 -> 70.597372 | O12: =L12+N12 -> 140.59737 | P12: =RANK(O12,$O$4:$O$29,0) -> 25 | Q12: =IF(RAND()<0.08,"DNF","OK") -> OK | S12: 1 | T12: 8
A13: J. McGrath | B13: 0 | C13: 5 | D13: 0 | E13: 0 | F13: 0 | G13: 0 | H13: 0 | I13: 0 | J13: 0 | K13: =SUM(B13:J13) -> 5 | L13: 70 | M13: =L13*$L$24 -> 6300 | N13: =L13+RAND()*6 -> 70.549989 | O13: =L13+N13 -> 140.54999 | P13: =RANK(O13,$O$4:$O$29,0) -> 26 | Q13: =IF(RAND()<0.08,"DNF","OK") -> DNF | S13: 2 | T13: 6
A14: L. Musso | B14: 1 | C14: 0 | D14: 0 | E14: 2 | F14: 0 | G14: 0 | H14: 0 | I14: 0 | J14: 2 | K14: =SUM(B14:J14) -> 5 | L14: 93 | M14: =L14*$L$24 -> 8370 | N14: =L14+RAND()*6 -> 93.420592 | O14: =L14+N14 -> 186.42059 | P14: =RANK(O14,$O$4:$O$29,0) -> 9 | Q14: =IF(RAND()<0.08,"DNF","OK") -> OK | S14: 3 | T14: 4
A15: M. Nazaruk | B15: 0 | C15: 2 | D15: 0 | E15: 0 | F15: DNF | G15: 0 | H15: 0 | I15: 0 | J15: 0 | K15: =SUM(B15:J15) -> 2 | L15: 70 | M15: =L15*$L$24 -> 6300 | N15: =L15+RAND()*6 -> 71.002191 | O15: =L15+N15 -> 141.00219 | P15: =RANK(O15,$O$4:$O$29,0) -> 24 | Q15: =IF(RAND()<0.08,"DNF","OK") -> OK | S15: 4 | T15: 3
A16: M. Trintignant | B16: 0 | C16: 0 | D16: 0 | E16: DNF | F16: 0 | G16: 0 | H16: 2 | I16: 0 | J16: 0 | K16: =SUM(B16:J16) -> 2 | L16: 93 | M16: =L16*$L$24 -> 8370 | N16: =L16+RAND()*6 -> 96.179781 | O16: =L16+N16 -> 189.17978 | P16: =RANK(O16,$O$4:$O$29,0) -> 7 | Q16: =IF(RAND()<0.08,"DNF","OK") -> OK | S16: 5 | T16: 2
A17: D. Carter | B17: 0 | C17: 1.5 | D17: 0 | E17: 0 | F17: 0 | G17: DNF | H17: 0 | I17: 0 | J17: 0 | K17: =SUM(B17:J17) -> 1.5 | L17: 70 | M17: =L17*$L$24 -> 6300 | N17: =L17+RAND()*6 -> 75.853949 | O17: =L17+N17 -> 145.85395 | P17: =RANK(O17,$O$4:$O$29,0) -> 20 | Q17: =IF(RAND()<0.08,"DNF","OK") -> OK | S17: 6 | T17: 1
A18: T. Ruttman | B18: 0 | C18: 1.5 | D18: 0 | E18: 0 | F18: 0 | G18: 0 | H18: 0 | I18: 0 | J18: 0 | K18: =SUM(B18:J18) -> 1.5 | L18: 70 | M18: =L18*$L$24 -> 6300 | N18: =L18+RAND()*6 -> 73.167643 | O18: =L18+N18 -> 143.16764 | P18: =RANK(O18,$O$4:$O$29,0) -> 23 | Q18: =IF(RAND()<0.08,"DNF","OK") -> OK | S18: 7 | T18: 0
A19: K. Kling | B19: 0 | C19: 0 | D19: 0 | E19: 0 | F19: 0 | G19: 0 | H19: 0 | I19: DNF | J19: 0 | K19: =SUM(B19:J19) -> 0 | L19: 90 | M19: =L19*$L$24 -> 8100 | N19: =L19+RAND()*6 -> 92.21633 | O19: =L19+N19 -> 182.21633 | P19: =RANK(O19,$O$4:$O$29,0) -> 11 | Q19: =IF(RAND()<0.08,"DNF","OK") -> OK | S19: 8 | T19: 0
A20: H. Herrmann | B20: 0 | C20: 0 | D20: 0 | E20: 0 | F20: DNF | G20: 0 | H20: 0 | I20: 0 | J20: 0 | K20: =SUM(B20:J20) -> 0 | L20: 89 | M20: =L20*$L$24 -> 8010 | N20: =L20+RAND()*6 -> 89.984648 | O20: =L20+N20 -> 178.98465 | P20: =RANK(O20,$O$4:$O$29,0) -> 16 | Q20: =IF(RAND()<0.08,"DNF","OK") -> OK | S20: 9 | T20: 0
A21: O. Marimon | B21: 0 | C21: 0 | D21: 0 | E21: 0 | F21: 0 | G21: 0 | H21: 0 | I21: DNF | J21: 0 | K21: =SUM(B21:J21) -> 0 | L21: 89 | M21: =L21*$L$24 -> 8010 | N21: =L21+RAND()*6 -> 90.241433 | O21: =L21+N21 -> 179.24143 | P21: =RANK(O21,$O$4:$O$29,0) -> 14 | Q21: =IF(RAND()<0.08,"DNF","OK") -> OK | S21: 10 | T21: 0
A22: R. Manzon | B22: 0 | C22: 0 | D22: 0 | E22: 0 | F22: 0 | G22: 0 | H22: 0 | I22: 0 | J22: 0 | K22: =SUM(B22:J22) -> 0 | L22: 89 | M22: =L22*$L$24 -> 8010 | N22: =L22+RAND()*6 -> 90.022326 | O22: =L22+N22 -> 179.02233 | P22: =RANK(O22,$O$4:$O$29,0) -> 15 | Q22: =IF(RAND()<0.08,"DNF","OK") -> OK
A23: S. Mantovani | B23: 0 | C23: 0 | D23: 0 | E23: DNF | F23: 0 | G23: 0 | H23: 0 | I23: 0 | J23: 0 | K23: =SUM(B23:J23) -> 0 | L23: 87 | M23: =L23*$L$24 -> 7830 | N23: =L23+RAND()*6 -> 87.14162 | O23: =L23+N23 -> 174.14162 | P23: =RANK(O23,$O$4:$O$29,0) -> 19 | Q23: =IF(RAND()<0.08,"DNF","OK") -> OK
A24: P. Bira | B24: 0 | C24: 0 | D24: 0 | E24: 0 | F24: 0 | G24: 0 | H24: 0 | I24: 0 | J24: 0 | K24: =SUM(B24:J24) -> 0 | L24: 90 | M24: =L24*$L$24 -> 8100 | N24: =L24+RAND()*6 -> 94.236396 | O24: =L24+N24 -> 184.2364 | P24: =RANK(O24,$O$4:$O$29,0) -> 10 | Q24: =IF(RAND()<0.08,"DNF","OK") -> OK
A25: U. Maglioli | B25: 0 | C25: 0 | D25: 0 | E25: 0 | F25: DNF | G25: 0 | H25: 0 | I25: 0 | J25: 0 | K25: =SUM(B25:J25) -> 0 | L25: 87 | M25: =L25*$L$24 -> 7830 | N25: =L25+RAND()*6 -> 87.836767 | O25: =L25+N25 -> 174.83677 | P25: =RANK(O25,$O$4:$O$29,0) -> 17 | Q25: =IF(RAND()<0.08,"DNF","OK") -> DNF
A26: A. Pilette | B26: 0 | C26: 0 | D26: 0 | E26: 0 | F26: 0 | G26: 0 | H26: DNF | I26: 0 | J26: 0 | K26: =SUM(B26:J26) -> 0 | L26: 86 | M26: =L26*$L$24 -> 7740 | N26: =L26+RAND()*6 -> 88.608487 | O26: =L26+N26 -> 174.60849 | P26: =RANK(O26,$O$4:$O$29,0) -> 18 | Q26: =IF(RAND()<0.08,"DNF","OK") -> OK
A27: E. Bayol | B27: 0 | C27: 0 | D27: 0 | E27: 0 | F27: 0 | G27: 0 | H27: 0 | I27: 0 | J27: 0 | K27: =SUM(B27:J27) -> 0 | L27: 70 | M27: =L27*$L$24 -> 6300 | N27: =L27+RAND()*6 -> 74.6136 | O27: =L27+N27 -> 144.6136 | P27: =RANK(O27,$O$4:$O$29,0) -> 21 | Q27: =IF(RAND()<0.08,"DNF","OK") -> OK
A28: A. Ascari | B28: 0 | C28: 0 | D28: 0 | E28: 0 | F28: 0 | G28: 0 | H28: 0 | I28: 0 | J28: 0 | K28: =SUM(B28:J28) -> 0 | L28: 89 | M28: =L28*$L$24 -> 8010 | N28: =L28+RAND()*6 -> 91.782786 | O28: =L28+N28 -> 180.78279 | P28: =RANK(O28,$O$4:$O$29,0) -> 13 | Q28: =IF(RAND()<0.08,"DNF","OK") -> OK
A29: J. Behra | B29: 0 | C29: 0 | D29: 0 | E29: 0 | F29: DNF | G29: 0 | H29: 0 | I29: 0 | J29: 0 | K29: =SUM(B29:J29) -> 0 | L29: 88 | M29: =L29*$L$24 -> 7920 | N29: =L29+RAND()*6 -> 93.669581 | O29: =L29+N29 -> 181.66958 | P29: =RANK(O29,$O$4:$O$29,0) -> 12 | Q29: =IF(RAND()<0.08,"DNF","OK") -> OK

Sheet 1955
A1: Formula 1 - Stagione 1955
A3: Pilota | B3: Argentina | C3: Monaco | D3: Indianapolis | E3: Belgio | F3: Paesi Bassi | G3: Gran Bretagna | H3: Italia | I3: Totale | J3: Overall | K3: Colonna1 | L3: Random | M3: Performance | N3: Posizione Finale | O3: Colonna2 | Q3: COME FUNZIONA
A4: J. Fangio | B4: 9 | C4: 9 | D4: 0 | E4: 8 | F4: 8 | G4: 3 | H4: 9 | I4: =SUM(B4:H4) -> 46 | J4: 97 | K4: =J4*$J$30 -> 210199 | L4: =J4+RAND()*6 -> 100.16329 | M4: =J4+L4 -> 197.16329 | N4: =RANK(M4,$M$4:$M$29,0) -> 1 | O4: =IF(RAND()<0.08,"DNF","OK") -> OK | Q4: 1. Modifica l'Overall dei piloti
A5: S. Moss | B5: 3 | C5: 3 | D5: 0 | E5: 5 | F5: 4 | G5: 9 | H5: 6 | I5: =SUM(B5:H5) -> 30 | J5: 96 | K5: =J5*$J$30 -> 208032 | L5: =J5+RAND()*6 -> 98.847248 | M5: =J5+L5 -> 194.84725 | N5: =RANK(M5,$M$4:$M$29,0) -> 3 | O5: =IF(RAND()<0.08,"DNF","OK") -> OK | Q5: 2. Premi F9 in Excel per rigenerare la casualità
A6: M. Trintigant | B6: 4 | C6: 6 | D6: 0 | E6: 3 | F6: 1 | G6: 4 | H6: 4 | I6: =SUM(B6:H6) -> 22 | J6: 95 | K6: =J6*$J$30 -> 205865 | L6: =J6+RAND()*6 -> 100.8453 | M6: =J6+L6 -> 195.8453 | N6: =RANK(M6,$M$4:$M$29,0) -> 2 | O6: =IF(RAND()<0.08,"DNF","OK") -> DNF | Q6: 3. Il valore Random simula incidenti, meteo, fortuna ecc.
A7: L. Villoresi | B7: 2 | C7: 4 | D7: 0 | E7: 6 | F7: 6 | G7: 2 | H7: DNF | I7: =SUM(B7:H7) -> 20 | J7: 95 | K7: =J7*$J$30 -> 205865 | L7: =J7+RAND()*6 -> 95.518427 | M7: =J7+L7 -> 190.51843 | N7: =RANK(M7,$M$4:$M$29,0) -> 7 | O7: =IF(RAND()<0.08,"DNF","OK") -> OK | Q7: 4. Performance = Overall + Casualità
A8: E. Castellotti | B8: 6 | C8: DNF | D8: 0 | E8: 2 | F8: 2 | G8: 6 | H8: 3 | I8: =SUM(B8:H8) -> 19 | J8: 95 | K8: =J8*$J$30 -> 205865 | L8: =J8+RAND()*6 -> 96.38528 | M8: =J8+L8 -> 191.38528 | N8: =RANK(M8,$M$4:$M$29,0) -> 5 | O8: =IF(RAND()<0.08,"DNF","OK") -> OK | Q8: 5. Posizione Finale aggiornata automaticamente
A9: B. Sweikert | B9: 0 | C9: 0 | D9: 8 | E9: 0 | F9: 0 | G9: 0 | H9: 0 | I9: =SUM(B9:H9) -> 8 | J9: 70 | K9: =J9*$J$30 -> 151690 | L9: =J9+RAND()*6 -> 71.975654 | M9: =J9+L9 -> 141.97565 | N9: =RANK(M9,$M$4:$M$29,0) -> 23 | O9: =IF(RAND()<0.08,"DNF","OK") -> OK
A10: J. Gonzalez | B10: DNF | C10: 0 | D10: 0 | E10: 0 | F10: 3 | G10: 0 | H10: 2 | I10: =SUM(B10:H10) -> 5 | J10: 93 | K10: =J10*$J$30 -> 201531 | L10: =J10+RAND()*6 -> 97.720657 | M10: =J10+L10 -> 190.72066 | N10: =RANK(M10,$M$4:$M$29,0) -> 6 | O10: =IF(RAND()<0.08,"DNF","OK") -> OK
A11: K. Davies | B11: 0 | C11: 0 | D11: 4 | E11: 0 | F11: 0 | G11: 0 | H11: 0 | I11: =SUM(B11:H11) -> 4 | J11: 70 | K11: =J11*$J$30 -> 151690 | L11: =J11+RAND()*6 -> 73.323193 | M11: =J11+L11 -> 143.32319 | N11: =RANK(M11,$M$4:$M$29,0) -> 18 | O11: =IF(RAND()<0.08,"DNF","OK") -> OK | Q11: Sistema Punti
A12: T. Bettenhausen | B12: 0 | C12: 0 | D12: 3 | E12: DNF | F12: 0 | G12: 0 | H12: 0 | I12: =SUM(B12:H12) -> 3 | J12: 70 | K12: =J12*$J$30 -> 151690 | L12: =J12+RAND()*6 -> 70.304462 | M12: =J12+L12 -> 140.30446 | N12: =RANK(M12,$M$4:$M$29,0) -> 26 | O12: =IF(RAND()<0.08,"DNF","OK") -> DNF | Q12: 1 | R12: 8
A13: P. Russo | B13: 0 | C13: 0 | D13: 3 | E13: 0 | F13: 0 | G13: DNF | H13: 0 | I13: =SUM(B13:H13) -> 3 | J13: 70 | K13: =J13*$J$30 -> 151690 | L13: =J13+RAND()*6 -> 70.454676 | M13: =J13+L13 -> 140.45468 | N13: =RANK(M13,$M$4:$M$29,0) -> 24 | O13: =IF(RAND()<0.08,"DNF","OK") -> DNF | Q13: 2 | R13: 6
A14: J. Thomson | B14: 0 | C14: 0 | D14: 3 | E14: 0 | F14: 0 | G14: 0 | H14: 0 | I14: =SUM(B14:H14) -> 3 | J14: 70 | K14: =J14*$J$30 -> 151690 | L14: =J14+RAND()*6 -> 75.301412 | M14: =J14+L14 -> 145.30141 | N14: =RANK(M14,$M$4:$M$29,0) -> 17 | O14: =IF(RAND()<0.08,"DNF","OK") -> OK | Q14: 3 | R14: 4
A15: G. Farina | B15: DNF | C15: 2 | D15: 0 | E15: 0 | F15: DNF | G15: 0 | H15: DNF | I15: =SUM(B15:H15) -> 2 | J15: 94 | K15: =J15*$J$30 -> 203698 | L15: =J15+RAND()*6 -> 99.129394 | M15: =J15+L15 -> 193.12939 | N15: =RANK(M15,$M$4:$M$29,0) -> 4 | O15: =IF(RAND()<0.08,"DNF","OK") -> OK | Q15: 4 | R15: 3
A16: W. Faulkner | B16: 0 | C16: 0 | D16: 1 | E16: 0 | F16: 0 | G16: 0 | H16: 0 | I16: =SUM(B16:H16) -> 1 | J16: 70 | K16: =J16*$J$30 -> 151690 | L16: =J16+RAND()*6 -> 72.201987 | M16: =J16+L16 -> 142.20199 | N16: =RANK(M16,$M$4:$M$29,0) -> 21 | O16: =IF(RAND()<0.08,"DNF","OK") -> DNF | Q16: 5 | R16: 2
A17: B. Homeier | B17: 0 | C17: 0 | D17: 1 | E17: 0 | F17: 0 | G17: 0 | H17: 0 | I17: =SUM(B17:H17) -> 1 | J17: 70 | K17: =J17*$J$30 -> 151690 | L17: =J17+RAND()*6 -> 72.179772 | M17: =J17+L17 -> 142.17977 | N17: =RANK(M17,$M$4:$M$29,0) -> 22 | O17: =IF(RAND()<0.08,"DNF","OK") -> DNF | Q17: 6 | R17: 0
A18: P. Taruffi | B18: 0 | C18: 0 | D18: 0 | E18: 0 | F18: 0 | G18: 0 | H18: DNF | I18: =SUM(B18:H18) -> 0 | J18: 93 | K18: =J18*$J$30 -> 201531 | L18: =J18+RAND()*6 -> 94.384405 | M18: =J18+L18 -> 187.38441 | N18: =RANK(M18,$M$4:$M$29,0) -> 8 | O18: =IF(RAND()<0.08,"DNF","OK") -> OK | Q18: 7 | R18: 0
A19: R. Mieres | B19: 0 | C19: 0 | D19: 0 | E19: 0 | F19: 0 | G19: 0 | H19: 0 | I19: =SUM(B19:H19) -> 0 | J19: 91 | K19: =J19*$J$30 -> 197197 | L19: =J19+RAND()*6 -> 93.002072 | M19: =J19+L19 -> 184.00207 | N19: =RANK(M19,$M$4:$M$29,0) -> 10 | O19: =IF(RAND()<0.08,"DNF","OK") -> OK | Q19: 8 | R19: 0
A20: J. Behra | B20: DNF | C20: DNF | D20: 0 | E20: DNF | F20: 0 | G20: 0 | H20: DNF | I20: =SUM(B20:H20) -> 0 | J20: 92 | K20: =J20*$J$30 -> 199364 | L20: =J20+RAND()*6 -> 94.000025 | M20: =J20+L20 -> 186.00003 | N20: =RANK(M20,$M$4:$M$29,0) -> 9 | O20: =IF(RAND()<0.08,"DNF","OK") -> OK | Q20: 9 | R20: 0
A21: L. Musso | B21: 0 | C21: 0 | D21: 0 | E21: 0 | F21: 0 | G21: 0 | H21: 0 | I21: =SUM(B21:H21) -> 0 | J21: 90 | K21: =J21*$J$30 -> 195030 | L21: =J21+RAND()*6 -> 93.920518 | M21: =J21+L21 -> 183.92052 | N21: =RANK(M21,$M$4:$M$29,0) -> 11 | O21: =IF(RAND()<0.08,"DNF","OK") -> OK | Q21: 10 | R21: 0
A22: K. Kling | B22: DNF | C22: 0 | D22: 0 | E22: 0 | F22: 0 | G22: 0 | H22: DNF | I22: =SUM(B22:H22) -> 0 | J22: 90 | K22: =J22*$J$30 -> 195030 | L22: =J22+RAND()*6 -> 92.020048 | M22: =J22+L22 -> 182.02005 | N22: =RANK(M22,$M$4:$M$29,0) -> 12 | O22: =IF(RAND()<0.08,"DNF","OK") -> OK
A23: P. Frere | B23: 0 | C23: 0 | D23: 0 | E23: 0 | F23: 0 | G23: 0 | H23: 0 | I23: =SUM(B23:H23) -> 0 | J23: 89 | K23: =J23*$J$30 -> 192863 | L23: =J23+RAND()*6 -> 90.14533 | M23: =J23+L23 -> 179.14533 | N23: =RANK(M23,$M$4:$M$29,0) -> 13 | O23: =IF(RAND()<0.08,"DNF","OK") -> OK
A24: C. Perdisa | B24: 0 | C24: 0 | D24: 0 | E24: 0 | F24: DNF | G24: 0 | H24: 0 | I24: =SUM(B24:H24) -> 0 | J24: 70 | K24: =J24*$J$30 -> 151690 | L24: =J24+RAND()*6 -> 73.124666 | M24: =J24+L24 -> 143.12467 | N24: =RANK(M24,$M$4:$M$29,0) -> 19 | O24: =IF(RAND()<0.08,"DNF","OK") -> OK
A25: C. Menditeguy | B25: 0 | C25: 0 | D25: 0 | E25: 0 | F25: 0 | G25: 0 | H25: 0 | I25: =SUM(B25:H25) -> 0 | J25: 87 | K25: =J25*$J$30 -> 188529 | L25: =J25+RAND()*6 -> 88.772859 | M25: =J25+L25 -> 175.77286 | N25: =RANK(M25,$M$4:$M$29,0) -> 14 | O25: =IF(RAND()<0.08,"DNF","OK") -> OK
A26: U. Magioli | B26: DNF | C26: 0 | D26: 0 | E26: 0 | F26: 0 | G26: 0 | H26: DNF | I26: =SUM(B26:H26) -> 0 | J26: 85 | K26: =J26*$J$30 -> 184195 | L26: =J26+RAND()*6 -> 86.929921 | M26: =J26+L26 -> 171.92992 | N26: =RANK(M26,$M$4:$M$29,0) -> 15 | O26: =IF(RAND()<0.08,"DNF","OK") -> OK
A27: H. Herrmann | B27: 0 | C27: 0 | D27: 0 | E27: 0 | F27: 0 | G27: 0 | H27: 0 | I27: =SUM(B27:H27) -> 0 | J27: 85 | K27: =J27*$J$30 -> 184195 | L27: =J27+RAND()*6 -> 86.608584 | M27: =J27+L27 -> 171.60858 | N27: =RANK(M27,$M$4:$M$29,0) -> 16 | O27: =IF(RAND()<0.08,"DNF","OK") -> OK
A28: B. Vukovic | B28: 0 | C28: 0 | D28: 0 | E28: 0 | F28: 0 | G28: 0 | H28: 0 | I28: =SUM(B28:H28) -> 0 | J28: 70 | K28: =J28*$J$30 -> 151690 | L28: =J28+RAND()*6 -> 73.021001 | M28: =J28+L28 -> 143.021 | N28: =RANK(M28,$M$4:$M$29,0) -> 20 | O28: =IF(RAND()<0.08,"DNF","OK") -> OK
A29: M. Hawthorn | B29: DNF | C29: 0 | D29: 0 | E29: 0 | F29: 0 | G29: 0 | H29: 0 | I29: =SUM(B29:H29) -> 0 | J29: 70 | K29: =J29*$J$30 -> 151690 | L29: =J29+RAND()*6 -> 70.414679 | M29: =J29+L29 -> 140.41468 | N29: =RANK(M29,$M$4:$M$29,0) -> 25 | O29: =IF(RAND()<0.08,"DNF","OK") -> OK
J30: =SUM(J4:J29) -> 2167

Sheet 1956
A1: Formula 1 - Stagione 1956
A3: Pilota | B3: Argentina | C3: Monaco | D3: Indianapolis | E3: Belgio | F3: Francia | G3: Gran Bretagna | H3: Germania | I3: Italia | J3: Totale | K3: Overall | L3: Colonna1 | M3: Random | N3: Performance | O3: Posizione Finale | P3: Colonna2 | R3: COME FUNZIONA
A4: J. Fangio | B4: 8 | C4: 8 | D4: 0 | E4: 3 | F4: 8 | G4: 9 | H4: 9 | I4: 8 | J4: =SUM(B4:I4) -> 53 | K4: 97 | L4: =K4*$K$31 -> 219899 | M4: =K4+RAND()*6 -> 97.983077 | N4: =K4+M4 -> 194.98308 | O4: =RANK(N4,$N$4:$N$29,0) -> 3 | P4: =IF(RAND()<0.08,"DNF","OK") -> OK | R4: 1. Modifica l'Overall dei piloti
A5: S. Moss | B5: 7 | C5: 6 | D5: 0 | E5: 9 | F5: 7 | G5: 6 | H5: 6 | I5: 7 | J5: =SUM(B5:I5) -> 48 | K5: 97 | L5: =K5*$K$30 -> 6790 | M5: =K5+RAND()*6 -> 101.87397 | N5: =K5+M5 -> 198.87397 | O5: =RANK(N5,$N$4:$N$29,0) -> 1 | P5: =IF(RAND()<0.08,"DNF","OK") -> OK | R5: 2. Premi F9 in Excel per rigenerare la casualità
A6: J. Behra | B6: 4 | C6: 2 | D6: 0 | E6: 2 | F6: 1 | G6: 4 | H6: 4 | I6: 2 | J6: =SUM(B6:I6) -> 19 | K6: 95 | L6: =K6*$K$30 -> 6650 | M6: =K6+RAND()*6 -> 97.885857 | N6: =K6+M6 -> 192.88586 | O6: =RANK(N6,$N$4:$N$29,0) -> 5 | P6: =IF(RAND()<0.08,"DNF","OK") -> OK | R6: 3. Il valore Random simula incidenti, meteo, fortuna ecc.
A7: L. Villoresi | B7: 1 | C7: 4 | D7: 0 | E7: 4 | F7: 0 | G7: 1 | H7: 2 | I7: 4 | J7: =SUM(B7:I7) -> 16 | K7: 95 | L7: =K7*$K$30 -> 6650 | M7: =K7+RAND()*6 -> 99.326781 | N7: =K7+M7 -> 194.32678 | O7: =RANK(N7,$N$4:$N$29,0) -> 4 | P7: =IF(RAND()<0.08,"DNF","OK") -> OK | R7: 4. Performance = Overall + Casualità
A8: E. Castellotti | B8: 0 | C8: 3 | D8: 0 | E8: 0 | F8: 4 | G8: 0 | H8: 3 | I8: 0 | J8: =SUM(B8:I8) -> 10 | K8: 94 | L8: =K8*$K$30 -> 6580 | M8: =K8+RAND()*6 -> 94.756322 | N8: =K8+M8 -> 188.75632 | O8: =RANK(N8,$N$4:$N$29,0) -> 7 | P8: =IF(RAND()<0.08,"DNF","OK") -> OK | R8: 5. Posizione Finale aggiornata automaticamente
A9: P. Collins | B9: 0 | C9: DNF | D9: 0 | E9: 6 | F9: 0 | G9: 2 | H9: DNF | I9: DNF | J9: =SUM(B9:I9) -> 8 | K9: 95 | L9: =K9*$K$30 -> 6650 | M9: =K9+RAND()*6 -> 100.65314 | N9: =K9+M9 -> 195.65314 | O9: =RANK(N9,$N$4:$N$29,0) -> 2 | P9: =IF(RAND()<0.08,"DNF","OK") -> OK
A10: P. Flaherty | B10: 0 | C10: DNF | D10: 8 | E10: 0 | F10: 0 | G10: 0 | H10: 0 | I10: 0 | J10: =SUM(B10:I10) -> 8 | K10: 70 | L10: =K10*$K$30 -> 4900 | M10: =K10+RAND()*6 -> 75.206588 | N10: =K10+M10 -> 145.20659 | O10: =RANK(N10,$N$4:$N$29,0) -> 21 | P10: =IF(RAND()<0.08,"DNF","OK") -> OK
A11: M. Hawthorn | B11: 2 | C11: 0 | D11: 0 | E11: 0 | F11: 2 | G11: 0 | H11: 0 | I11: 3 | J11: =SUM(B11:I11) -> 7 | K11: 94 | L11: =K11*$K$30 -> 6580 | M11: =K11+RAND()*6 -> 97.649781 | N11: =K11+M11 -> 191.64978 | O11: =RANK(N11,$N$4:$N$29,0) -> 6 | P11: =IF(RAND()<0.08,"DNF","OK") -> OK | R11: Sistema Punti
A12: S. Hanks | B12: 0 | C12: 0 | D12: 6 | E12: 0 | F12: 0 | G12: 0 | H12: 0 | I12: 0 | J12: =SUM(B12:I12) -> 6 | K12: 70 | L12: =K12*$K$30 -> 4900 | M12: =K12+RAND()*6 -> 71.291271 | N12: =K12+M12 -> 141.29127 | O12: =RANK(N12,$N$4:$N$29,0) -> 26 | P12: =IF(RAND()<0.08,"DNF","OK") -> OK | R12: 1 | S12: 8
A13: D. Freeland | B13: 0 | C13: 0 | D13: 4 | E13: 0 | F13: 0 | G13: 0 | H13: 0 | I13: 0 | J13: =SUM(B13:I13) -> 4 | K13: 70 | L13: =K13*$K$30 -> 4900 | M13: =K13+RAND()*6 -> 74.335976 | N13: =K13+M13 -> 144.33598 | O13: =RANK(N13,$N$4:$N$29,0) -> 22 | P13: =IF(RAND()<0.08,"DNF","OK") -> OK | R13: 2 | S13: 6
A14: J. Parsons | B14: 0 | C14: 0 | D14: 3 | E14: DNF | F14: 0 | G14: 0 | H14: 0 | I14: 0 | J14: =SUM(B14:I14) -> 3 | K14: 79 | L14: =K14*$K$30 -> 5530 | M14: =K14+RAND()*6 -> 81.138503 | N14: =K14+M14 -> 160.1385 | O14: =RANK(N14,$N$4:$N$29,0) -> 18 | P14: =IF(RAND()<0.08,"DNF","OK") -> OK | R14: 3 | S14: 4
A15: D. Rathmann | B15: 0 | C15: 0 | D15: 2 | E15: 0 | F15: 0 | G15: 0 | H15: 0 | I15: 0 | J15: =SUM(B15:I15) -> 2 | K15: 70 | L15: =K15*$K$30 -> 4900 | M15: =K15+RAND()*6 -> 72.139196 | N15: =K15+M15 -> 142.1392 | O15: =RANK(N15,$N$4:$N$29,0) -> 24 | P15: =IF(RAND()<0.08,"DNF","OK") -> OK | R15: 4 | S15: 3
A16: P. Frere | B16: 0 | C16: 0 | D16: 0 | E16: 0 | F16: 0 | G16: 0 | H16: 0 | I16: 0 | J16: =SUM(B16:I16) -> 0 | K16: 70 | L16: =K16*$K$30 -> 4900 | M16: =K16+RAND()*6 -> 75.729434 | N16: =K16+M16 -> 145.72943 | O16: =RANK(N16,$N$4:$N$29,0) -> 20 | P16: =IF(RAND()<0.08,"DNF","OK") -> DNF | R16: 5 | S16: 2
A17: F. Godia-Sales | B17: 0 | C17: 0 | D17: 0 | E17: 0 | F17: 0 | G17: DNF | H17: 0 | I17: DNF | J17: =SUM(B17:I17) -> 0 | K17: 89 | L17: =K17*$K$30 -> 6230 | M17: =K17+RAND()*6 -> 92.805027 | N17: =K17+M17 -> 181.80503 | O17: =RANK(N17,$N$4:$N$29,0) -> 10 | P17: =IF(RAND()<0.08,"DNF","OK") -> OK | R17: 6 | S17: 0
A18: H. Fairman | B18: 0 | C18: 0 | D18: 0 | E18: 0 | F18: 0 | G18: 0 | H18: 0 | I18: 0 | J18: =SUM(B18:I18) -> 0 | K18: 85 | L18: =K18*$K$30 -> 5950 | M18: =K18+RAND()*6 -> 85.34693 | N18: =K18+M18 -> 170.34693 | O18: =RANK(N18,$N$4:$N$29,0) -> 17 | P18: =IF(RAND()<0.08,"DNF","OK") -> OK | R18: 7 | S18: 0
A19: L. Musso | B19: 0 | C19: 0 | D19: 0 | E19: 0 | F19: DNF | G19: 0 | H19: 0 | I19: 0 | J19: =SUM(B19:I19) -> 0 | K19: 89 | L19: =K19*$K$30 -> 6230 | M19: =K19+RAND()*6 -> 92.703469 | N19: =K19+M19 -> 181.70347 | O19: =RANK(N19,$N$4:$N$29,0) -> 11 | P19: =IF(RAND()<0.08,"DNF","OK") -> OK | R19: 8 | S19: 0
A20: R. Flockhart | B20: 0 | C20: 0 | D20: 0 | E20: 0 | F20: 0 | G20: 0 | H20: 0 | I20: 0 | J20: =SUM(B20:I20) -> 0 | K20: 75 | L20: =K20*$K$30 -> 5250 | M20: =K20+RAND()*6 -> 77.508624 | N20: =K20+M20 -> 152.50862 | O20: =RANK(N20,$N$4:$N$29,0) -> 19 | P20: =IF(RAND()<0.08,"DNF","OK") -> OK | R20: 9 | S20: 0
A21: C. Perdisa | B21: 0 | C21: 0 | D21: 0 | E21: 0 | F21: 0 | G21: 0 | H21: DNF | I21: 0 | J21: =SUM(B21:I21) -> 0 | K21: 89 | L21: =K21*$K$30 -> 6230 | M21: =K21+RAND()*6 -> 90.502221 | N21: =K21+M21 -> 179.50222 | O21: =RANK(N21,$N$4:$N$29,0) -> 14 | P21: =IF(RAND()<0.08,"DNF","OK") -> DNF | R21: 10 | S21: 0
A22: H. Schell | B22: 0 | C22: 0 | D22: 0 | E22: 0 | F22: 0 | G22: 0 | H22: 0 | I22: 0 | J22: =SUM(B22:I22) -> 0 | K22: 90 | L22: =K22*$K$30 -> 6300 | M22: =K22+RAND()*6 -> 93.576133 | N22: =K22+M22 -> 183.57613 | O22: =RANK(N22,$N$4:$N$29,0) -> 9 | P22: =IF(RAND()<0.08,"DNF","OK") -> OK
A23: A. de Portago | B23: 0 | C23: 0 | D23: 0 | E23: 0 | F23: 0 | G23: 0 | H23: 0 | I23: 0 | J23: =SUM(B23:I23) -> 0 | K23: 88 | L23: =K23*$K$30 -> 6160 | M23: =K23+RAND()*6 -> 89.397997 | N23: =K23+M23 -> 177.398 | O23: =RANK(N23,$N$4:$N$29,0) -> 15 | P23: =IF(RAND()<0.08,"DNF","OK") -> OK
A24: L. Rosier | B24: 0 | C24: 0 | D24: 0 | E24: 0 | F24: 0 | G24: 0 | H24: 0 | I24: 0 | J24: =SUM(B24:I24) -> 0 | K24: 87 | L24: =K24*$K$30 -> 6090 | M24: =K24+RAND()*6 -> 88.341512 | N24: =K24+M24 -> 175.34151 | O24: =RANK(N24,$N$4:$N$29,0) -> 16 | P24: =IF(RAND()<0.08,"DNF","OK") -> OK
A25: H. da Silva Ramos | B25: 0 | C25: DNF | D25: 0 | E25: 0 | F25: 0 | G25: 0 | H25: 0 | I25: 0 | J25: =SUM(B25:I25) -> 0 | K25: 90 | L25: =K25*$K$30 -> 6300 | M25: =K25+RAND()*6 -> 94.608405 | N25: =K25+M25 -> 184.60841 | O25: =RANK(N25,$N$4:$N$29,0) -> 8 | P25: =IF(RAND()<0.08,"DNF","OK") -> OK
A26: H. Gould | B26: 0 | C26: 0 | D26: 0 | E26: 0 | F26: 0 | G26: 0 | H26: 0 | I26: 0 | J26: =SUM(B26:I26) -> 0 | K26: 90 | L26: =K26*$K$30 -> 6300 | M26: =K26+RAND()*6 -> 91.369153 | N26: =K26+M26 -> 181.36915 | O26: =RANK(N26,$N$4:$N$29,0) -> 12 | P26: =IF(RAND()<0.08,"DNF","OK") -> OK
A27: O. Gendebien | B27: 0 | C27: 0 | D27: 0 | E27: 0 | F27: 0 | G27: 0 | H27: 0 | I27: DNF | J27: =SUM(B27:I27) -> 0 | K27: 89 | L27: =K27*$K$30 -> 6230 | M27: =K27+RAND()*6 -> 90.783684 | N27: =K27+M27 -> 179.78368 | O27: =RANK(N27,$N$4:$N$29,0) -> 13 | P27: =IF(RAND()<0.08,"DNF","OK") -> OK
A28: G. Gerini | B28: 0 | C28: 0 | D28: 0 | E28: DNF | F28: 0 | G28: DNF | H28: 0 | I28: 0 | J28: =SUM(B28:I28) -> 0 | K28: 70 | L28: =K28*$K$30 -> 4900 | M28: =K28+RAND()*6 -> 73.652324 | N28: =K28+M28 -> 143.65232 | O28: =RANK(N28,$N$4:$N$29,0) -> 23 | P28: =IF(RAND()<0.08,"DNF","OK") -> OK
A29: C. Landi | B29: 0 | C29: 0 | D29: 0 | E29: 0 | F29: 0 | G29: DNF | H29: 0 | I29: 0 | J29: =SUM(B29:I29) -> 0 | K29: 70 | L29: =K29*$K$30 -> 4900 | M29: =K29+RAND()*6 -> 71.357759 | N29: =K29+M29 -> 141.35776 | O29: =RANK(N29:N30,$N$4:$N$29,0) -> 25 | P29: =IF(RAND()<0.08,"DNF","OK") -> OK
A30: P. Russo | B30: 0 | C30: 0 | D30: 0 | E30: 0 | F30: 0 | G30: 0 | H30: 0 | I30: 0 | J30: =SUM(B30:I30) -> 0 | K30: 70 | L30: =K30*$K$30 -> 4900 | M30: =K30+RAND()*6 -> 75.08073 | N30: =K30+M30 -> 145.08073 | O30: =RANK(N30,$N$4:$N$30,0) -> 22 | P30: =IF(RAND()<0.08,"DNF","OK") -> OK
K31: =SUM(K4:K30) -> 2267

Sheet 1957
A1: Formula 1 - Stagione 1957
A3: Pilota | B3: Argentina | C3: Monaco | D3: Indianapolis | E3: Francia | F3: Gran Bretagna | G3: Germania | H3: Pescara | I3: Italia | J3: Totale | K3: Overall | L3: Colonna1 | M3: Random | N3: Performance | O3: Posizione Finale | P3: Colonna2 | R3: COME FUNZIONA
A4: J. Fangio | B4: 8 | C4: 6 | D4: 0 | E4: 9 | F4: 7 | G4: 8 | H4: 9 | I4: 6 | J4: =SUM(B4:I4) -> 53 | K4: 97 | L4: =K4*$K$30 -> 0 | M4: =K4+RAND()*6 -> 102.99004 | N4: =K4+M4 -> 199.99004 | O4: =RANK(N4,$N$4:$N$29,0) -> 1 | P4: =IF(RAND()<0.08,"DNF","OK") -> OK | R4: 1. Modifica l'Overall dei piloti
A5: M. Hawthorn | B5: 6 | C5: 9 | D5: 0 | E5: 6 | F5: 4 | G5: 3 | H5: DNF | I5: 8 | J5: =SUM(B5:I5) -> 36 | K5: 96 | L5: =K5*$K$30 -> 0 | M5: =K5+RAND()*6 -> 97.886767 | N5: =K5+M5 -> 193.88677 | O5: =RANK(N5,$N$4:$N$29,0) -> 3 | P5: =IF(RAND()<0.08,"DNF","OK") -> OK | R5: 2. Premi F9 in Excel per rigenerare la casualità
A6: S. Moss | B6: 5 | C6: DNF | D6: 0 | E6: DNF | F6: 8 | G6: 5 | H6: 6 | I6: 4 | J6: =SUM(B6:I6) -> 28 | K6: 96 | L6: =K6*$K$30 -> 0 | M6: =K6+RAND()*6 -> 97.266004 | N6: =K6+M6 -> 193.266 | O6: =RANK(N6,$N$4:$N$29,0) -> 6 | P6: =IF(RAND()<0.08,"DNF","OK") -> DNF | R6: 3. Il valore Random simula incidenti, meteo, fortuna ecc.
A7: J. Behra | B7: 2 | C7: 3 | D7: 0 | E7: 4 | F7: 3 | G7: 6 | H7: 2 | I7: 0 | J7: =SUM(B7:I7) -> 20 | K7: 95 | L7: =K7*$K$30 -> 0 | M7: =K7+RAND()*6 -> 97.512791 | N7: =K7+M7 -> 192.51279 | O7: =RANK(N7,$N$4:$N$29,0) -> 7 | P7: =IF(RAND()<0.08,"DNF","OK") -> OK | R7: 4. Performance = Overall + Casualità
A8: T. Brooks | B8: 3 | C8: 0 | D8: 0 | E8: 2 | F8: 0 | G8: 0 | H8: 4 | I8: 0 | J8: =SUM(B8:I8) -> 9 | K8: 95 | L8: =K8*$K$30 -> 0 | M8: =K8+RAND()*6 -> 100.70338 | N8: =K8+M8 -> 195.70338 | O8: =RANK(N8,$N$4:$N$29,0) -> 2 | P8: =IF(RAND()<0.08,"DNF","OK") -> OK | R8: 5. Posizione Finale aggiornata automaticamente
A9: S. Hanks | B9: DNF | C9: 0 | D9: 8 | E9: 0 | F9: 0 | G9: 0 | H9: 0 | I9: 0 | J9: =SUM(B9:I9) -> 8 | K9: 70 | L9: =K9*$K$30 -> 0 | M9: =K9+RAND()*6 -> 73.507744 | N9: =K9+M9 -> 143.50774 | O9: =RANK(N9,$N$4:$N$29,0) -> 23 | P9: =IF(RAND()<0.08,"DNF","OK") -> OK
A10: L. Musso | B10: 0 | C10: 0 | D10: 0 | E10: 3 | F10: 0 | G10: 2 | H10: 0 | I10: 3 | J10: =SUM(B10:I10) -> 8 | K10: 95 | L10: =K10*$K$30 -> 0 | M10: =K10+RAND()*6 -> 95.469649 | N10: =K10+M10 -> 190.46965 | O10: =RANK(N10,$N$4:$N$29,0) -> 9 | P10: =IF(RAND()<0.08,"DNF","OK") -> OK
A11: J. Rathmann | B11: 0 | C11: 0 | D11: 7 | E11: 0 | F11: 0 | G11: 0 | H11: 0 | I11: DNF | J11: =SUM(B11:I11) -> 7 | K11: 70 | L11: =K11*$K$30 -> 0 | M11: =K11+RAND()*6 -> 70.015094 | N11: =K11+M11 -> 140.01509 | O11: =RANK(N11,$N$4:$N$29,0) -> 26 | P11: =IF(RAND()<0.08,"DNF","OK") -> OK | R11: Sistema Punti
A12: P. Collins | B12: 0 | C12: 4 | D12: 0 | E12: 0 | F12: 0 | G12: 0 | H12: 0 | I12: 2 | J12: =SUM(B12:I12) -> 6 | K12: 94 | L12: =K12*$K$30 -> 0 | M12: =K12+RAND()*6 -> 99.708091 | N12: =K12+M12 -> 193.70809 | O12: =RANK(N12,$N$4:$N$29,0) -> 4 | P12: =IF(RAND()<0.08,"DNF","OK") -> OK | R12: 1 | S12: 8
A13: W. Von Trips | B13: 0 | C13: 0 | D13: 0 | E13: 0 | F13: 2 | G13: 0 | H13: 3 | I13: 0 | J13: =SUM(B13:I13) -> 5 | K13: 94 | L13: =K13*$K$30 -> 0 | M13: =K13+RAND()*6 -> 99.466557 | N13: =K13+M13 -> 193.46656 | O13: =RANK(N13,$N$4:$N$29,0) -> 5 | P13: =IF(RAND()<0.08,"DNF","OK") -> OK | R13: 2 | S13: 6
A14: J. Bryan | B14: 0 | C14: 0 | D14: 4 | E14: 0 | F14: 0 | G14: DNF | H14: 0 | I14: 0 | J14: =SUM(B14:I14) -> 4 | K14: 70 | L14: =K14*$K$30 -> 0 | M14: =K14+RAND()*6 -> 72.727469 | N14: =K14+M14 -> 142.72747 | O14: =RANK(N14,$N$4:$N$29,0) -> 24 | P14: =IF(RAND()<0.08,"DNF","OK") -> DNF | R14: 3 | S14: 4
A15: P. Russo | B15: 0 | C15: 0 | D15: 3 | E15: 0 | F15: 0 | G15: 0 | H15: 0 | I15: 0 | J15: =SUM(B15:I15) -> 3 | K15: 70 | L15: =K15*$K$30 -> 0 | M15: =K15+RAND()*6 -> 74.915563 | N15: =K15+M15 -> 144.91556 | O15: =RANK(N15,$N$4:$N$29,0) -> 22 | P15: =IF(RAND()<0.08,"DNF","OK") -> OK | R15: 4 | S15: 3
A16: H. Schell | B16: 0 | C16: 2 | D16: 0 | E16: 0 | F16: 0 | G16: 0 | H16: 0 | I16: 0 | J16: =SUM(B16:I16) -> 2 | K16: 93 | L16: =K16*$K$30 -> 0 | M16: =K16+RAND()*6 -> 98.274263 | N16: =K16+M16 -> 191.27426 | O16: =RANK(N16,$N$4:$N$29,0) -> 8 | P16: =IF(RAND()<0.08,"DNF","OK") -> OK | R16: 5 | S16: 2
A17: A. Linden | B17: 0 | C17: 0 | D17: 2 | E17: 0 | F17: 0 | G17: 0 | H17: 0 | I17: 0 | J17: =SUM(B17:I17) -> 2 | K17: 70 | L17: =K17*$K$30 -> 0 | M17: =K17+RAND()*6 -> 70.846209 | N17: =K17+M17 -> 140.84621 | O17: =RANK(N17,$N$4:$N$29,0) -> 25 | P17: =IF(RAND()<0.08,"DNF","OK") -> OK | R17: 6 | S17: 0
A18: M. Gregory | B18: 0 | C18: 0 | D18: 0 | E18: 0 | F18: 0 | G18: 0 | H18: 0 | I18: 0 | J18: =SUM(B18:I18) -> 0 | K18: 93 | L18: =K18*$K$30 -> 0 | M18: =K18+RAND()*6 -> 94.703336 | N18: =K18+M18 -> 187.70334 | O18: =RANK(N18,$N$4:$N$29,0) -> 12 | P18: =IF(RAND()<0.08,"DNF","OK") -> OK | R18: 7 | S18: 0
A19: S. Lewis-Evans | B19: 0 | C19: 0 | D19: 0 | E19: 0 | F19: 0 | G19: 0 | H19: 0 | I19: 0 | J19: =SUM(B19:I19) -> 0 | K19: 92 | L19: =K19*$K$30 -> 0 | M19: =K19+RAND()*6 -> 94.014311 | N19: =K19+M19 -> 186.01431 | O19: =RANK(N19,$N$4:$N$29,0) -> 13 | P19: =IF(RAND()<0.08,"DNF","OK") -> OK | R19: 8 | S19: 0
A20: M. Trintignant | B20: 0 | C20: 0 | D20: 0 | E20: 0 | F20: 0 | G20: 0 | H20: 0 | I20: 0 | J20: =SUM(B20:I20) -> 0 | K20: 93 | L20: =K20*$K$30 -> 0 | M20: =K20+RAND()*6 -> 96.195522 | N20: =K20+M20 -> 189.19552 | O20: =RANK(N20,$N$4:$N$29,0) -> 11 | P20: =IF(RAND()<0.08,"DNF","OK") -> OK | R20: 9 | S20: 0
A21: C. Menditeguy | B21: 0 | C21: 0 | D21: 0 | E21: 0 | F21: 0 | G21: 0 | H21: 0 | I21: 0 | J21: =SUM(B21:I21) -> 0 | K21: 92 | L21: =K21*$K$30 -> 0 | M21: =K21+RAND()*6 -> 97.959258 | N21: =K21+M21 -> 189.95926 | O21: =RANK(N21,$N$4:$N$29,0) -> 10 | P21: =IF(RAND()<0.08,"DNF","OK") -> OK | R21: 10 | S21: 0
A22: R. Salvadori | B22: 0 | C22: 0 | D22: 0 | E22: 0 | F22: 0 | G22: DNF | H22: 0 | I22: DNF | J22: =SUM(B22:I22) -> 0 | K22: 89 | L22: =K22*$K$30 -> 0 | M22: =K22+RAND()*6 -> 91.051699 | N22: =K22+M22 -> 180.0517 | O22: =RANK(N22,$N$4:$N$29,0) -> 15 | P22: =IF(RAND()<0.08,"DNF","OK") -> OK
A23: G. Scarlatti | B23: 0 | C23: 0 | D23: 0 | E23: 0 | F23: 0 | G23: 0 | H23: 0 | I23: 0 | J23: =SUM(B23:I23) -> 0 | K23: 89 | L23: =K23*$K$30 -> 0 | M23: =K23+RAND()*6 -> 92.140997 | N23: =K23+M23 -> 181.141 | O23: =RANK(N23,$N$4:$N$29,0) -> 14 | P23: =IF(RAND()<0.08,"DNF","OK") -> DNF
A24: A. de Portago | B24: 0 | C24: 0 | D24: 0 | E24: 0 | F24: 0 | G24: 0 | H24: 0 | I24: 0 | J24: =SUM(B24:I24) -> 0 | K24: 87 | L24: =K24*$K$30 -> 0 | M24: =K24+RAND()*6 -> 90.73763 | N24: =K24+M24 -> 177.73763 | O24: =RANK(N24,$N$4:$N$29,0) -> 16 | P24: =IF(RAND()<0.08,"DNF","OK") -> OK
